Workbook

Sheet Sheet1
A1: REKAP TABUNGAN SISWA
A2: SMK GLOBIN
A4: Kelas | C4: XII - OTKP 1
A5: Tahun Ajaran | C5: 2025/2026
A6: Total Tabungan | C6: =SUM(F9:F58) -> 3219000
A8: NO | B8: NIS | C8: NAMA SISWA | D8: SETORAN | E8: PENARIKAN | F8: SALDO AKHIR
A9: =IF(C9<>"",ROW()-8,"") -> 1 | B9: 231001284 | C9: AENA NUR BAENI | D9: ='1'!C6 -> 43000 | E9: ='1'!C7 -> 0 | F9: ='1'!C8 -> 43000
A10: =IF(C10<>"",ROW()-8,"") -> 2 | B10: 231001285 | C10: AENI NURBAYANI | D10: ='2'!C6 -> 43000 | E10: ='2'!C7 -> 0 | F10: ='2'!C8 -> 43000
A11: =IF(C11<>"",ROW()-8,"") -> 3 | B11: 231001286 | C11: ALYA RAMADHANI | D11: ='3'!C6 -> 80000 | E11: ='3'!C7 -> 0 | F11: ='3'!C8 -> 80000
A12: =IF(C12<>"",ROW()-8,"") -> 4 | B12: 231001287 | C12: ARIFFAH FARLY | D12: ='4'!C6 -> 48000 | E12: ='4'!C7 -> 0 | F12: ='4'!C8 -> 48000
A13: =IF(C13<>"",ROW()-8,"") -> 5 | B13: 231001288 | C13: DAVINA | D13: ='5'!C6 -> 31000 | E13: ='5'!C7 -> 0 | F13: ='5'!C8 -> 31000
A14: =IF(C14<>"",ROW()-8,"") -> 6 | B14: 231001289 | C14: DELA LESTARI | D14: ='6'!C6 -> 85000 | E14: ='6'!C7 -> 0 | F14: ='6'!C8 -> 85000
A15: =IF(C15<>"",ROW()-8,"") -> 7 | B15: 231001290 | C15: DIMAS ERLANGGA | D15: ='7'!C6 -> 84000 | E15: ='7'!C7 -> 0 | F15: ='7'!C8 -> 84000
A16: =IF(C16<>"",ROW()-8,"") -> 8 | B16: 231001291 | C16: DINI ANJANI NUR AENI | D16: ='8'!C6 -> 38000 | E16: ='8'!C7 -> 0 | F16: ='8'!C8 -> 38000
A17: =IF(C17<>"",ROW()-8,"") -> 9 | B17: 231001292 | C17: FITRYA | D17: ='9'!C6 -> 109000 | E17: ='9'!C7 -> 0 | F17: ='9'!C8 -> 109000
A18: =IF(C18<>"",ROW()-8,"") -> 10 | B18: 231001293 | C18: HALIMATUSSADIAH | D18: ='10'!C6 -> 132000 | E18: ='10'!C7 -> 0 | F18: ='10'!C8 -> 132000
A19: =IF(C19<>"",ROW()-8,"") -> 11 | B19: 231001294 | C19: IKSAN NUGRAHA | D19: ='11'!C6 -> 18000 | E19: ='11'!C7 -> 0 | F19: ='11'!C8 -> 18000
A20: =IF(C20<>"",ROW()-8,"") -> 12 | B20: 231001295 | C20: JULIA | D20: ='12'!C6 -> 100000 | E20: ='12'!C7 -> 100000 | F20: ='12'!C8 -> 0
A21: =IF(C21<>"",ROW()-8,"") -> 13 | B21: 231001296 | C21: KANANTI MAHARDINI | D21: ='13'!C6 -> 64000 | E21: ='13'!C7 -> 50000 | F21: ='13'!C8 -> 14000
A22: =IF(C22<>"",ROW()-8,"") -> 14 | B22: 231001299 | C22: M. IRWAN RUHIANSYAH | D22: ='14'!C6 -> 150000 | E22: ='14'!C7 -> 15000 | F22: ='14'!C8 -> 135000
A23: =IF(C23<>"",ROW()-8,"") -> 15 | B23: 231001297 | C23: MEYLANI SRI RAHAYU | D23: ='15'!C6 -> 100000 | E23: ='15'!C7 -> 0 | F23: ='15'!C8 -> 100000
A24: =IF(C24<>"",ROW()-8,"") -> 16 | B24: 231001298 | C24: MORENO RAFAEL RADITYA NANDA | D24: ='16'!C6 -> 305000 | E24: ='16'!C7 -> 0 | F24: ='16'!C8 -> 305000
A25: =IF(C25<>"",ROW()-8,"") -> 17 | B25: 231001408 | C25: MUHAMAD ABYANSAH | D25: ='17'!C6 -> 80000 | E25: ='17'!C7 -> 0 | F25: ='17'!C8 -> 80000
A26: =IF(C26<>"",ROW()-8,"") -> 18 | B26: 231001413 | C26: MUHAMAD RASYA | D26: ='18'!C6 -> 66000 | E26: ='18'!C7 -> 50000 | F26: ='18'!C8 -> 16000
A27: =IF(C27<>"",ROW()-8,"") -> 19 | B27: 231001301 | C27: MUHAMAD TIRTA YASA | D27: ='19'!C6 -> 57000 | E27: ='19'!C7 -> 0 | F27: ='19'!C8 -> 57000
A28: =IF(C28<>"",ROW()-8,"") -> 20 | B28: 231001303 | C28: MUTIA SULISTIAWATI | D28: ='20'!C6 -> 205000 | E28: ='20'!C7 -> 0 | F28: ='20'!C8 -> 205000
A29: =IF(C29<>"",ROW()-8,"") -> 21 | B29: 231001304 | C29: NABILA SAKIB | D29: ='21'!C6 -> 67000 | E29: ='21'!C7 -> 0 | F29: ='21'!C8 -> 67000
A30: =IF(C30<>"",ROW()-8,"") -> 22 | B30: 231001305 | C30: NANDA ASSIFA | D30: ='22'!C6 -> 50000 | E30: ='22'!C7 -> 0 | F30: ='22'!C8 -> 50000
A31: =IF(C31<>"",ROW()-8,"") -> 23 | B31: 231001306 | C31: PUTRI ANISA | D31: ='23'!C6 -> 55000 | E31: ='23'!C7 -> 0 | F31: ='23'!C8 -> 55000
A32: =IF(C32<>"",ROW()-8,"") -> 24 | B32: 231001307 | C32: QAIS NUR SYAHRANI | D32: ='24'!C6 -> 50000 | E32: ='24'!C7 -> 0 | F32: ='24'!C8 -> 50000
A33: =IF(C33<>"",ROW()-8,"") -> 25 | B33: 231001309 | C33: RIKA AJENG OKTAPIA | D33: ='25'!C6 -> 135000 | E33: ='25'!C7 -> 0 | F33: ='25'!C8 -> 135000
A34: =IF(C34<>"",ROW()-8,"") -> 26 | B34: 231001310 | C34: RIKI BAYU KRISTI | D34: ='26'!C6 -> 11000 | E34: ='26'!C7 -> 0 | F34: ='26'!C8 -> 11000
A35: =IF(C35<>"",ROW()-8,"") -> 27 | B35: 231001311 | C35: RIZKI RIPATULLOH | D35: ='27'!C6 -> 145000 | E35: ='27'!C7 -> 0 | F35: ='27'!C8 -> 145000
A36: =IF(C36<>"",ROW()-8,"") -> 28 | B36: 231001312 | C36: SALSA NABILA NUR FITRIA | D36: ='28'!C6 -> 79000 | E36: ='28'!C7 -> 50000 | F36: ='28'!C8 -> 29000
A37: =IF(C37<>"",ROW()-8,"") -> 29 | B37: 231001314 | C37: SHYSIL HERLYA RAMADHANI | D37: ='29'!C6 -> 94000 | E37: ='29'!C7 -> 0 | F37: ='29'!C8 -> 94000
A38: =IF(C38<>"",ROW()-8,"") -> 30 | B38: 231001315 | C38: SIFA ANINDIA | D38: ='30'!C6 -> 100000 | E38: ='30'!C7 -> 75000 | F38: ='30'!C8 -> 25000
A39: =IF(C39<>"",ROW()-8,"") -> 31 | B39: 231001316 | C39: SITI HANNA MUZVIROH | D39: ='31'!C6 -> 280000 | E39: ='31'!C7 -> 0 | F39: ='31'!C8 -> 280000
A40: =IF(C40<>"",ROW()-8,"") -> 32 | B40: 231001317 | C40: SITI MAULIDA KARATUA | D40: ='32'!C6 -> 28000 | E40: ='32'!C7 -> 0 | F40: ='32'!C8 -> 28000
A41: =IF(C41<>"",ROW()-8,"") -> 33 | B41: 231001318 | C41: SITI MUFLIHAH OKTAVIANI | D41: ='33'!C6 -> 122000 | E41: ='33'!C7 -> 0 | F41: ='33'!C8 -> 122000
A42: =IF(C42<>"",ROW()-8,"") -> 34 | B42: 231001319 | C42: SITI NUR PADILAH | D42: ='34'!C6 -> 82000 | E42: ='34'!C7 -> 0 | F42: ='34'!C8 -> 82000
...

Sheet 1
A1: BUKU TABUNGAN SISWA
A3: Nama | C3: =Sheet1!C9 -> AENA NUR BAENI
A4: NIS | C4: =Sheet1!B9 -> 231001284
A5: Kelas | C5: =Sheet1!C4 -> XII - OTKP 1
A6: Jumlah Setoran | C6: =SUM(C12:C376) -> 43000
A7: Jumlah Penarikan | C7: =SUM(D12:D376) -> 0
A8: Saldo Tabungan | C8: =SUM(C6-C7) -> 43000
A11: NO | B11: TANGGAL | C11: SETORAN | D11: PENARIKAN | E11: SALDO
A12: =IF(B12<>"",ROW()-11,"") -> 1 | B12: 45852 | C12: 39000 | E12: =IF(B12<>"",C12-D12,"") -> 39000 | I12: 1
A13: =IF(B13<>"",ROW()-11,"") -> 2 | B13: 45853 | E13: =IF(B13<>"",E12+C13-D13,"") -> 39000 | I13: 2
A14: =IF(B14<>"",ROW()-11,"") -> 3 | B14: 45854 | E14: =IF(B14<>"",E13+C14-D14,"") -> 39000 | I14: 3
A15: =IF(B15<>"",ROW()-11,"") -> 4 | B15: 45855 | E15: =IF(B15<>"",E14+C15-D15,"") -> 39000 | I15: 4
A16: =IF(B16<>"",ROW()-11,"") -> 5 | B16: 45856 | E16: =IF(B16<>"",E15+C16-D16,"") -> 39000 | I16: 5
A17: =IF(B17<>"",ROW()-11,"") -> 6 | B17: 45857 | E17: =IF(B17<>"",E16+C17-D17,"") -> 39000 | I17: 6
A18: =IF(B18<>"",ROW()-11,"") -> 7 | B18: 45858 | E18: =IF(B18<>"",E17+C18-D18,"") -> 39000 | I18: 7
A19: =IF(B19<>"",ROW()-11,"") -> 8 | B19: 45859 | E19: =IF(B19<>"",E18+C19-D19,"") -> 39000 | I19: 8
A20: =IF(B20<>"",ROW()-11,"") -> 9 | B20: 45860 | E20: =IF(B20<>"",E19+C20-D20,"") -> 39000 | I20: 9
A21: =IF(B21<>"",ROW()-11,"") -> 10 | B21: 45861 | E21: =IF(B21<>"",E20+C21-D21,"") -> 39000 | I21: 10
A22: =IF(B22<>"",ROW()-11,"") -> 11 | B22: 45862 | C22: 2000 | E22: =IF(B22<>"",E21+C22-D22,"") -> 41000 | I22: 11
A23: =IF(B23<>"",ROW()-11,"") -> 12 | B23: 45863 | E23: =IF(B23<>"",E22+C23-D23,"") -> 41000 | I23: 12
A24: =IF(B24<>"",ROW()-11,"") -> 13 | B24: 45864 | E24: =IF(B24<>"",E23+C24-D24,"") -> 41000 | I24: 13
A25: =IF(B25<>"",ROW()-11,"") -> 14 | B25: 45865 | E25: =IF(B25<>"",E24+C25-D25,"") -> 41000 | I25: 14
A26: =IF(B26<>"",ROW()-11,"") -> 15 | B26: 45866 | E26: =IF(B26<>"",E25+C26-D26,"") -> 41000 | I26: 15
A27: =IF(B27<>"",ROW()-11,"") -> 16 | B27: 45867 | E27: =IF(B27<>"",E26+C27-D27,"") -> 41000 | I27: 16
A28: =IF(B28<>"",ROW()-11,"") -> 17 | B28: 45868 | E28: =IF(B28<>"",E27+C28-D28,"") -> 41000 | I28: 17
A29: =IF(B29<>"",ROW()-11,"") -> 18 | B29: 45869 | E29: =IF(B29<>"",E28+C29-D29,"") -> 41000 | I29: 18
A30: =IF(B30<>"",ROW()-11,"") -> 19 | B30: 45870 | E30: =IF(B30<>"",E29+C30-D30,"") -> 41000 | I30: 19
A31: =IF(B31<>"",ROW()-11,"") -> 20 | B31: 45871 | E31: =IF(B31<>"",E30+C31-D31,"") -> 41000 | I31: 20
A32: =IF(B32<>"",ROW()-11,"") -> 21 | B32: 45872 | E32: =IF(B32<>"",E31+C32-D32,"") -> 41000 | I32: 21
A33: =IF(B33<>"",ROW()-11,"") -> 22 | B33: 45873 | C33: 2000 | E33: =IF(B33<>"",E32+C33-D33,"") -> 43000 | I33: 22
A34: =IF(B34<>"",ROW()-11,"") -> 23 | B34: 45874 | E34: =IF(B34<>"",E33+C34-D34,"") -> 43000 | I34: 23
A35: =IF(B35<>"",ROW()-11,"") -> 24 | B35: 45875 | E35: =IF(B35<>"",E34+C35-D35,"") -> 43000 | I35: 24
A36: =IF(B36<>"",ROW()-11,"") -> 25 | B36: 45876 | E36: =IF(B36<>"",E35+C36-D36,"") -> 43000 | I36: 25
A37: =IF(B37<>"",ROW()-11,"") -> 26 | B37: 45877 | E37: =IF(B37<>"",E36+C37-D37,"") -> 43000 | I37: 26
A38: =IF(B38<>"",ROW()-11,"") -> 27 | B38: 45878 | E38: =IF(B38<>"",E37+C38-D38,"") -> 43000 | I38: 27
A39: =IF(B39<>"",ROW()-11,"") -> 28 | B39: 45879 | E39: =IF(B39<>"",E38+C39-D39,"") -> 43000 | I39: 28
A40: =IF(B40<>"",ROW()-11,"") -> 29 | B40: 45880 | E40: =IF(B40<>"",E39+C40-D40,"") -> 43000 | I40: 29
A41: =IF(B41<>"",ROW()-11,"") -> 30 | B41: 45881 | E41: =IF(B41<>"",E40+C41-D41,"") -> 43000 | I41: 30
A42: =IF(B42<>"",ROW()-11,"") -> 31 | B42: 45882 | E42: =IF(B42<>"",E41+C42-D42,"") -> 43000 | I42: 31
A43: =IF(B43<>"",ROW()-11,"") -> 32 | B43: 45883 | E43: =IF(B43<>"",E42+C43-D43,"") -> 43000 | I43: 32
...

Sheet 2
A1: BUKU TABUNGAN SISWA
A3: Nama | C3: =Sheet1!C10 -> AENI NURBAYANI
A4: NIS | C4: =Sheet1!B10 -> 231001285
A5: Kelas | C5: =Sheet1!C4 -> XII - OTKP 1
A6: Jumlah Setoran | C6: =SUM(C12:C376) -> 43000
A7: Jumlah Penarikan | C7: =SUM(D12:D376) -> 0
A8: Saldo Tabungan | C8: =SUM(C6-C7) -> 43000
A11: NO | B11: TANGGAL | C11: SETORAN | D11: PENARIKAN | E11: SALDO
A12: =IF(B12<>"",ROW()-11,"") -> 1 | B12: 45852 | C12: 39000 | E12: =IF(B12<>"",C12-D12,"") -> 39000 | I12: 1
A13: =IF(B13<>"",ROW()-11,"") -> 2 | B13: 45853 | E13: =IF(B13<>"",E12+C13-D13,"") -> 39000 | I13: 2
A14: =IF(B14<>"",ROW()-11,"") -> 3 | B14: 45854 | E14: =IF(B14<>"",E13+C14-D14,"") -> 39000 | I14: 3
A15: =IF(B15<>"",ROW()-11,"") -> 4 | B15: 45855 | E15: =IF(B15<>"",E14+C15-D15,"") -> 39000 | I15: 4
A16: =IF(B16<>"",ROW()-11,"") -> 5 | B16: 45856 | E16: =IF(B16<>"",E15+C16-D16,"") -> 39000 | I16: 5
A17: =IF(B17<>"",ROW()-11,"") -> 6 | B17: 45857 | E17: =IF(B17<>"",E16+C17-D17,"") -> 39000 | I17: 6
A18: =IF(B18<>"",ROW()-11,"") -> 7 | B18: 45858 | E18: =IF(B18<>"",E17+C18-D18,"") -> 39000 | I18: 7
A19: =IF(B19<>"",ROW()-11,"") -> 8 | B19: 45859 | E19: =IF(B19<>"",E18+C19-D19,"") -> 39000 | I19: 8
A20: =IF(B20<>"",ROW()-11,"") -> 9 | B20: 45860 | E20: =IF(B20<>"",E19+C20-D20,"") -> 39000 | I20: 9
A21: =IF(B21<>"",ROW()-11,"") -> 10 | B21: 45861 | E21: =IF(B21<>"",E20+C21-D21,"") -> 39000 | I21: 10
A22: =IF(B22<>"",ROW()-11,"") -> 11 | B22: 45862 | C22: 2000 | E22: =IF(B22<>"",E21+C22-D22,"") -> 41000 | I22: 11
A23: =IF(B23<>"",ROW()-11,"") -> 12 | B23: 45863 | E23: =IF(B23<>"",E22+C23-D23,"") -> 41000 | I23: 12
A24: =IF(B24<>"",ROW()-11,"") -> 13 | B24: 45864 | E24: =IF(B24<>"",E23+C24-D24,"") -> 41000 | I24: 13
A25: =IF(B25<>"",ROW()-11,"") -> 14 | B25: 45865 | E25: =IF(B25<>"",E24+C25-D25,"") -> 41000 | I25: 14
A26: =IF(B26<>"",ROW()-11,"") -> 15 | B26: 45866 | E26: =IF(B26<>"",E25+C26-D26,"") -> 41000 | I26: 15
A27: =IF(B27<>"",ROW()-11,"") -> 16 | B27: 45867 | E27: =IF(B27<>"",E26+C27-D27,"") -> 41000 | I27: 16
A28: =IF(B28<>"",ROW()-11,"") -> 17 | B28: 45868 | E28: =IF(B28<>"",E27+C28-D28,"") -> 41000 | I28: 17
A29: =IF(B29<>"",ROW()-11,"") -> 18 | B29: 45869 | E29: =IF(B29<>"",E28+C29-D29,"") -> 41000 | I29: 18
A30: =IF(B30<>"",ROW()-11,"") -> 19 | B30: 45870 | E30: =IF(B30<>"",E29+C30-D30,"") -> 41000 | I30: 19
A31: =IF(B31<>"",ROW()-11,"") -> 20 | B31: 45871 | E31: =IF(B31<>"",E30+C31-D31,"") -> 41000 | I31: 20
A32: =IF(B32<>"",ROW()-11,"") -> 21 | B32: 45872 | E32: =IF(B32<>"",E31+C32-D32,"") -> 41000 | I32: 21
A33: =IF(B33<>"",ROW()-11,"") -> 22 | B33: 45873 | C33: 2000 | E33: =IF(B33<>"",E32+C33-D33,"") -> 43000 | I33: 22
A34: =IF(B34<>"",ROW()-11,"") -> 23 | B34: 45874 | E34: =IF(B34<>"",E33+C34-D34,"") -> 43000 | I34: 23
A35: =IF(B35<>"",ROW()-11,"") -> 24 | B35: 45875 | E35: =IF(B35<>"",E34+C35-D35,"") -> 43000 | I35: 24
A36: =IF(B36<>"",ROW()-11,"") -> 25 | B36: 45876 | E36: =IF(B36<>"",E35+C36-D36,"") -> 43000 | I36: 25
A37: =IF(B37<>"",ROW()-11,"") -> 26 | B37: 45877 | E37: =IF(B37<>"",E36+C37-D37,"") -> 43000 | I37: 26
A38: =IF(B38<>"",ROW()-11,"") -> 27 | B38: 45878 | E38: =IF(B38<>"",E37+C38-D38,"") -> 43000 | I38: 27
A39: =IF(B39<>"",ROW()-11,"") -> 28 | B39: 45879 | E39: =IF(B39<>"",E38+C39-D39,"") -> 43000 | I39: 28
A40: =IF(B40<>"",ROW()-11,"") -> 29 | B40: 45880 | E40: =IF(B40<>"",E39+C40-D40,"") -> 43000 | I40: 29
A41: =IF(B41<>"",ROW()-11,"") -> 30 | B41: 45881 | E41: =IF(B41<>"",E40+C41-D41,"") -> 43000 | I41: 30
A42: =IF(B42<>"",ROW()-11,"") -> 31 | B42: 45882 | E42: =IF(B42<>"",E41+C42-D42,"") -> 43000 | I42: 31
A43: =IF(B43<>"",ROW()-11,"") -> 32 | B43: 45883 | E43: =IF(B43<>"",E42+C43-D43,"") -> 43000 | I43: 32
...

Sheet 3
A1: BUKU TABUNGAN SISWA
A3: Nama | C3: =Sheet1!C11 -> ALYA RAMADHANI
A4: NIS | C4: =Sheet1!B11 -> 231001286
A5: Kelas | C5: =Sheet1!C4 -> XII - OTKP 1
A6: Jumlah Setoran | C6: =SUM(C12:C376) -> 80000
A7: Jumlah Penarikan | C7: =SUM(D12:D376) -> 0
A8: Saldo Tabungan | C8: =SUM(C6-C7) -> 80000
A11: NO | B11: TANGGAL | C11: SETORAN | D11: PENARIKAN | E11: SALDO
A12: =IF(B12<>"",ROW()-11,"") -> 1 | B12: 45852 | C12: 75000 | E12: =IF(B12<>"",C12-D12,"") -> 75000 | I12: 1
A13: =IF(B13<>"",ROW()-11,"") -> 2 | B13: 45853 | E13: =IF(B13<>"",E12+C13-D13,"") -> 75000 | I13: 2
A14: =IF(B14<>"",ROW()-11,"") -> 3 | B14: 45854 | E14: =IF(B14<>"",E13+C14-D14,"") -> 75000 | I14: 3
A15: =IF(B15<>"",ROW()-11,"") -> 4 | B15: 45855 | E15: =IF(B15<>"",E14+C15-D15,"") -> 75000 | I15: 4
A16: =IF(B16<>"",ROW()-11,"") -> 5 | B16: 45856 | E16: =IF(B16<>"",E15+C16-D16,"") -> 75000 | I16: 5
A17: =IF(B17<>"",ROW()-11,"") -> 6 | B17: 45857 | E17: =IF(B17<>"",E16+C17-D17,"") -> 75000 | I17: 6
A18: =IF(B18<>"",ROW()-11,"") -> 7 | B18: 45858 | E18: =IF(B18<>"",E17+C18-D18,"") -> 75000 | I18: 7
A19: =IF(B19<>"",ROW()-11,"") -> 8 | B19: 45859 | E19: =IF(B19<>"",E18+C19-D19,"") -> 75000 | I19: 8
A20: =IF(B20<>"",ROW()-11,"") -> 9 | B20: 45860 | E20: =IF(B20<>"",E19+C20-D20,"") -> 75000 | I20: 9
A21: =IF(B21<>"",ROW()-11,"") -> 10 | B21: 45861 | E21: =IF(B21<>"",E20+C21-D21,"") -> 75000 | I21: 10
A22: =IF(B22<>"",ROW()-11,"") -> 11 | B22: 45862 | E22: =IF(B22<>"",E21+C22-D22,"") -> 75000 | I22: 11
A23: =IF(B23<>"",ROW()-11,"") -> 12 | B23: 45863 | E23: =IF(B23<>"",E22+C23-D23,"") -> 75000 | I23: 12
A24: =IF(B24<>"",ROW()-11,"") -> 13 | B24: 45864 | E24: =IF(B24<>"",E23+C24-D24,"") -> 75000 | I24: 13
... A98: =IF(B98<>"",ROW()-11,"") -> 87 | B98: 45938 | E98: =IF(B98<>"",E97+C98-D98,"") -> 75000 | I98: 87
A99: =IF(B99<>"",ROW()-11,"") -> 88 | B99: 45939 | C99: 5000 | E99: =IF(B99<>"",E98+C99-D99,"") -> 80000 | I99: 88
A100: =IF(B100<>"",ROW()-11,"") -> 89 | B100: 45940 | E100: =IF(B100<>"",E99+C100-D100,"") -> 80000 | I100: 89
A101: =IF(B101<>"",ROW()-11,"") -> 90 | B101: 45941 | E101: =IF(B101<>"",E100+C101-D101,"") -> 80000 | I101: 90
A102: =IF(B102<>"",ROW()-11,"") -> 91 | B102: 45942 | E102: =IF(B102<>"",E101+C102-D102,"") -> 80000 | I102: 91
A103: =IF(B103<>"",ROW()-11,"") -> 92 | B103: 45943 | E103: =IF(B103<>"",E102+C103-D103,"") -> 80000 | I103: 92
A104: =IF(B104<>"",ROW()-11,"") -> 93 | B104: 45944 | E104: =IF(B104<>"",E103+C104-D104,"") -> 80000 | I104: 93
A105: =IF(B105<>"",ROW()-11,"") -> 94 | B105: 45945 | E105: =IF(B105<>"",E104+C105-D105,"") -> 80000 | I105: 94
A106: =IF(B106<>"",ROW()-11,"") -> 95 | B106: 45946 | E106: =IF(B106<>"",E105+C106-D106,"") -> 80000 | I106: 95
A107: =IF(B107<>"",ROW()-11,"") -> 96 | B107: 45947 | E107: =IF(B107<>"",E106+C107-D107,"") -> 80000 | I107: 96
A108: =IF(B108<>"",ROW()-11,"") -> 97 | B108: 45948 | E108: =IF(B108<>"",E107+C108-D108,"") -> 80000 | I108: 97
A109: =IF(B109<>"",ROW()-11,"") -> 98 | B109: 45949 | E109: =IF(B109<>"",E108+C109-D109,"") -> 80000 | I109: 98
A110: =IF(B110<>"",ROW()-11,"") -> 99 | B110: 45950 | E110: =IF(B110<>"",E109+C110-D110,"") -> 80000 | I110: 99
A111: =IF(B111<>"",ROW()-11,"") -> 100 | B111: 45951 | E111: =IF(B111<>"",E110+C111-D111,"") -> 80000 | I111: 100
... A376: =IF(B376<>"",ROW()-11,"") -> 365 | B376: 46216 | E376: =IF(B376<>"",E375+C376-D376,"") -> 80000 | I376: 365

Sheet 4
A1: BUKU TABUNGAN SISWA
A3: Nama | C3: =Sheet1!C12 -> ARIFFAH FARLY
A4: NIS | C4: =Sheet1!B12 -> 231001287
A5: Kelas | C5: =Sheet1!C4 -> XII - OTKP 1
A6: Jumlah Setoran | C6: =SUM(C12:C376) -> 48000
A7: Jumlah Penarikan | C7: =SUM(D12:D376) -> 0
A8: Saldo Tabungan | C8: =SUM(C6-C7) -> 48000
A11: NO | B11: TANGGAL | C11: SETORAN | D11: PENARIKAN | E11: SALDO
A12: =IF(B12<>"",ROW()-11,"") -> 1 | B12: 45852 | C12: 41000 | E12: =IF(B12<>"",C12-D12,"") -> 41000 | I12: 1
A13: =IF(B13<>"",ROW()-11,"") -> 2 | B13: 45853 | E13: =IF(B13<>"",E12+C13-D13,"") -> 41000 | I13: 2
A14: =IF(B14<>"",ROW()-11,"") -> 3 | B14: 45854 | E14: =IF(B14<>"",E13+C14-D14,"") -> 41000 | I14: 3
A15: =IF(B15<>"",ROW()-11,"") -> 4 | B15: 45855 | E15: =IF(B15<>"",E14+C15-D15,"") -> 41000 | I15: 4
A16: =IF(B16<>"",ROW()-11,"") -> 5 | B16: 45856 | E16: =IF(B16<>"",E15+C16-D16,"") -> 41000 | I16: 5
A17: =IF(B17<>"",ROW()-11,"") -> 6 | B17: 45857 | E17: =IF(B17<>"",E16+C17-D17,"") -> 41000 | I17: 6
A18: =IF(B18<>"",ROW()-11,"") -> 7 | B18: 45858 | E18: =IF(B18<>"",E17+C18-D18,"") -> 41000 | I18: 7
A19: =IF(B19<>"",ROW()-11,"") -> 8 | B19: 45859 | E19: =IF(B19<>"",E18+C19-D19,"") -> 41000 | I19: 8
A20: =IF(B20<>"",ROW()-11,"") -> 9 | B20: 45860 | E20: =IF(B20<>"",E19+C20-D20,"") -> 41000 | I20: 9
A21: =IF(B21<>"",ROW()-11,"") -> 10 | B21: 45861 | E21: =IF(B21<>"",E20+C21-D21,"") -> 41000 | I21: 10
A22: =IF(B22<>"",ROW()-11,"") -> 11 | B22: 45862 | E22: =IF(B22<>"",E21+C22-D22,"") -> 41000 | I22: 11
A23: =IF(B23<>"",ROW()-11,"") -> 12 | B23: 45863 | E23: =IF(B23<>"",E22+C23-D23,"") -> 41000 | I23: 12
A24: =IF(B24<>"",ROW()-11,"") -> 13 | B24: 45864 | E24: =IF(B24<>"",E23+C24-D24,"") -> 41000 | I24: 13
... A32: =IF(B32<>"",ROW()-11,"") -> 21 | B32: 45872 | E32: =IF(B32<>"",E31+C32-D32,"") -> 41000 | I32: 21
A33: =IF(B33<>"",ROW()-11,"") -> 22 | B33: 45873 | C33: 5000 | E33: =IF(B33<>"",E32+C33-D33,"") -> 46000 | I33: 22
A34: =IF(B34<>"",ROW()-11,"") -> 23 | B34: 45874 | E34: =IF(B34<>"",E33+C34-D34,"") -> 46000 | I34: 23
A35: =IF(B35<>"",ROW()-11,"") -> 24 | B35: 45875 | C35: 2000 | E35: =IF(B35<>"",E34+C35-D35,"") -> 48000 | I35: 24
A36: =IF(B36<>"",ROW()-11,"") -> 25 | B36: 45876 | E36: =IF(B36<>"",E35+C36-D36,"") -> 48000 | I36: 25
A37: =IF(B37<>"",ROW()-11,"") -> 26 | B37: 45877 | E37: =IF(B37<>"",E36+C37-D37,"") -> 48000 | I37: 26
A38: =IF(B38<>"",ROW()-11,"") -> 27 | B38: 45878 | E38: =IF(B38<>"",E37+C38-D38,"") -> 48000 | I38: 27
A39: =IF(B39<>"",ROW()-11,"") -> 28 | B39: 45879 | E39: =IF(B39<>"",E38+C39-D39,"") -> 48000 | I39: 28
A40: =IF(B40<>"",ROW()-11,"") -> 29 | B40: 45880 | E40: =IF(B40<>"",E39+C40-D40,"") -> 48000 | I40: 29
A41: =IF(B41<>"",ROW()-11,"") -> 30 | B41: 45881 | E41: =IF(B41<>"",E40+C41-D41,"") -> 48000 | I41: 30
A42: =IF(B42<>"",ROW()-11,"") -> 31 | B42: 45882 | E42: =IF(B42<>"",E41+C42-D42,"") -> 48000 | I42: 31
A43: =IF(B43<>"",ROW()-11,"") -> 32 | B43: 45883 | E43: =IF(B43<>"",E42+C43-D43,"") -> 48000 | I43: 32
A44: =IF(B44<>"",ROW()-11,"") -> 33 | B44: 45884 | E44: =IF(B44<>"",E43+C44-D44,"") -> 48000 | I44: 33
A45: =IF(B45<>"",ROW()-11,"") -> 34 | B45: 45885 | E45: =IF(B45<>"",E44+C45-D45,"") -> 48000 | I45: 34
A46: =IF(B46<>"",ROW()-11,"") -> 35 | B46: 45886 | E46: =IF(B46<>"",E45+C46-D46,"") -> 48000 | I46: 35
A47: =IF(B47<>"",ROW()-11,"") -> 36 | B47: 45887 | E47: =IF(B47<>"",E46+C47-D47,"") -> 48000 | I47: 36
... A376: =IF(B376<>"",ROW()-11,"") -> 365 | B376: 46216 | E376: =IF(B376<>"",E375+C376-D376,"") -> 48000 | I376: 365

Sheet 5
A1: BUKU TABUNGAN SISWA
A3: Nama | C3: =Sheet1!C13 -> DAVINA
A4: NIS | C4: =Sheet1!B13 -> 231001288
A5: Kelas | C5: =Sheet1!C4 -> XII - OTKP 1
A6: Jumlah Setoran | C6: =SUM(C12:C376) -> 31000
A7: Jumlah Penarikan | C7: =SUM(D12:D376) -> 0
A8: Saldo Tabungan | C8: =SUM(C6-C7) -> 31000
A11: NO | B11: TANGGAL | C11: SETORAN | D11: PENARIKAN | E11: SALDO
A12: =IF(B12<>"",ROW()-11,"") -> 1 | B12: 45852 | C12: 31000 | E12: =IF(B12<>"",C12-D12,"") -> 31000 | I12: 1
A13: =IF(B13<>"",ROW()-11,"") -> 2 | B13: 45853 | E13: =IF(B13<>"",E12+C13-D13,"") -> 31000 | I13: 2
A14: =IF(B14<>"",ROW()-11,"") -> 3 | B14: 45854 | E14: =IF(B14<>"",E13+C14-D14,"") -> 31000 | I14: 3
A15: =IF(B15<>"",ROW()-11,"") -> 4 | B15: 45855 | E15: =IF(B15<>"",E14+C15-D15,"") -> 31000 | I15: 4
A16: =IF(B16<>"",ROW()-11,"") -> 5 | B16: 45856 | E16: =IF(B16<>"",E15+C16-D16,"") -> 31000 | I16: 5
A17: =IF(B17<>"",ROW()-11,"") -> 6 | B17: 45857 | E17: =IF(B17<>"",E16+C17-D17,"") -> 31000 | I17: 6
A18: =IF(B18<>"",ROW()-11,"") -> 7 | B18: 45858 | E18: =IF(B18<>"",E17+C18-D18,"") -> 31000 | I18: 7
A19: =IF(B19<>"",ROW()-11,"") -> 8 | B19: 45859 | E19: =IF(B19<>"",E18+C19-D19,"") -> 31000 | I19: 8
A20: =IF(B20<>"",ROW()-11,"") -> 9 | B20: 45860 | E20: =IF(B20<>"",E19+C20-D20,"") -> 31000 | I20: 9
A21: =IF(B21<>"",ROW()-11,"") -> 10 | B21: 45861 | E21: =IF(B21<>"",E20+C21-D21,"") -> 31000 | I21: 10
A22: =IF(B22<>"",ROW()-11,"") -> 11 | B22: 45862 | E22: =IF(B22<>"",E21+C22-D22,"") -> 31000 | I22: 11
A23: =IF(B23<>"",ROW()-11,"") -> 12 | B23: 45863 | E23: =IF(B23<>"",E22+C23-D23,"") -> 31000 | I23: 12
A24: =IF(B24<>"",ROW()-11,"") -> 13 | B24: 45864 | E24: =IF(B24<>"",E23+C24-D24,"") -> 31000 | I24: 13
... A376: =IF(B376<>"",ROW()-11,"") -> 365 | B376: 46216 | E376: =IF(B376<>"",E375+C376-D376,"") -> 31000 | I376: 365

Sheet 6
A1: BUKU TABUNGAN SISWA
A3: Nama | C3: =Sheet1!C14 -> DELA LESTARI
A4: NIS | C4: =Sheet1!B14 -> 231001289
A5: Kelas | C5: =Sheet1!C4 -> XII - OTKP 1
A6: Jumlah Setoran | C6: =SUM(C12:C376) -> 85000
A7: Jumlah Penarikan | C7: =SUM(D12:D376) -> 0
A8: Saldo Tabungan | C8: =SUM(C6-C7) -> 85000
A11: NO | B11: TANGGAL | C11: SETORAN | D11: PENARIKAN | E11: SALDO
A12: =IF(B12<>"",ROW()-11,"") -> 1 | B12: 45852 | C12: 45000 | E12: =IF(B12<>"",C12-D12,"") -> 45000 | I12: 1
A13: =IF(B13<>"",ROW()-11,"") -> 2 | B13: 45853 | E13: =IF(B13<>"",E12+C13-D13,"") -> 45000 | I13: 2
A14: =IF(B14<>"",ROW()-11,"") -> 3 | B14: 45854 | E14: =IF(B14<>"",E13+C14-D14,"") -> 45000 | I14: 3
A15: =IF(B15<>"",ROW()-11,"") -> 4 | B15: 45855 | E15: =IF(B15<>"",E14+C15-D15,"") -> 45000 | I15: 4
A16: =IF(B16<>"",ROW()-11,"") -> 5 | B16: 45856 | E16: =IF(B16<>"",E15+C16-D16,"") -> 45000 | I16: 5
A17: =IF(B17<>"",ROW()-11,"") -> 6 | B17: 45857 | E17: =IF(B17<>"",E16+C17-D17,"") -> 45000 | I17: 6
A18: =IF(B18<>"",ROW()-11,"") -> 7 | B18: 45858 | E18: =IF(B18<>"",E17+C18-D18,"") -> 45000 | I18: 7
A19: =IF(B19<>"",ROW()-11,"") -> 8 | B19: 45859 | E19: =IF(B19<>"",E18+C19-D19,"") -> 45000 | I19: 8
A20: =IF(B20<>"",ROW()-11,"") -> 9 | B20: 45860 | C20: 5000 | E20: =IF(B20<>"",E19+C20-D20,"") -> 50000 | I20: 9
A21: =IF(B21<>"",ROW()-11,"") -> 10 | B21: 45861 | E21: =IF(B21<>"",E20+C21-D21,"") -> 50000 | I21: 10
A22: =IF(B22<>"",ROW()-11,"") -> 11 | B22: 45862 | E22: =IF(B22<>"",E21+C22-D22,"") -> 50000 | I22: 11
A23: =IF(B23<>"",ROW()-11,"") -> 12 | B23: 45863 | E23: =IF(B23<>"",E22+C23-D23,"") -> 50000 | I23: 12
A24: =IF(B24<>"",ROW()-11,"") -> 13 | B24: 45864 | E24: =IF(B24<>"",E23+C24-D24,"") -> 50000 | I24: 13
A25: =IF(B25<>"",ROW()-11,"") -> 14 | B25: 45865 | E25: =IF(B25<>"",E24+C25-D25,"") -> 50000 | I25: 14
A26: =IF(B26<>"",ROW()-11,"") -> 15 | B26: 45866 | E26: =IF(B26<>"",E25+C26-D26,"") -> 50000 | I26: 15
A27: =IF(B27<>"",ROW()-11,"") -> 16 | B27: 45867 | E27: =IF(B27<>"",E26+C27-D27,"") -> 50000 | I27: 16
A28: =IF(B28<>"",ROW()-11,"") -> 17 | B28: 45868 | E28: =IF(B28<>"",E27+C28-D28,"") -> 50000 | I28: 17
A29: =IF(B29<>"",ROW()-11,"") -> 18 | B29: 45869 | E29: =IF(B29<>"",E28+C29-D29,"") -> 50000 | I29: 18
A30: =IF(B30<>"",ROW()-11,"") -> 19 | B30: 45870 | E30: =IF(B30<>"",E29+C30-D30,"") -> 50000 | I30: 19
A31: =IF(B31<>"",ROW()-11,"") -> 20 | B31: 45871 | E31: =IF(B31<>"",E30+C31-D31,"") -> 50000 | I31: 20
A32: =IF(B32<>"",ROW()-11,"") -> 21 | B32: 45872 | E32: =IF(B32<>"",E31+C32-D32,"") -> 50000 | I32: 21
... A50: =IF(B50<>"",ROW()-11,"") -> 39 | B50: 45890 | E50: =IF(B50<>"",E49+C50-D50,"") -> 50000 | I50: 39
A51: =IF(B51<>"",ROW()-11,"") -> 40 | B51: 45891 | C51: 5000 | E51: =IF(B51<>"",E50+C51-D51,"") -> 55000 | I51: 40
A52: =IF(B52<>"",ROW()-11,"") -> 41 | B52: 45892 | E52: =IF(B52<>"",E51+C52-D52,"") -> 55000 | I52: 41
A53: =IF(B53<>"",ROW()-11,"") -> 42 | B53: 45893 | E53: =IF(B53<>"",E52+C53-D53,"") -> 55000 | I53: 42
A54: =IF(B54<>"",ROW()-11,"") -> 43 | B54: 45894 | E54: =IF(B54<>"",E53+C54-D54,"") -> 55000 | I54: 43
A55: =IF(B55<>"",ROW()-11,"") -> 44 | B55: 45895 | E55: =IF(B55<>"",E54+C55-D55,"") -> 55000 | I55: 44
A56: =IF(B56<>"",ROW()-11,"") -> 45 | B56: 45896 | E56: =IF(B56<>"",E55+C56-D56,"") -> 55000 | I56: 45
A57: =IF(B57<>"",ROW()-11,"") -> 46 | B57: 45897 | E57: =IF(B57<>"",E56+C57-D57,"") -> 55000 | I57: 46
A58: =IF(B58<>"",ROW()-11,"") -> 47 | B58: 45898 | E58: =IF(B58<>"",E57+C58-D58,"") -> 55000 | I58: 47
A59: =IF(B59<>"",ROW()-11,"") -> 48 | B59: 45899 | E59: =IF(B59<>"",E58+C59-D59,"") -> 55000 | I59: 48
A60: =IF(B60<>"",ROW()-11,"") -> 49 | B60: 45900 | E60: =IF(B60<>"",E59+C60-D60,"") -> 55000 | I60: 49
...

Sheet 7
A1: BUKU TABUNGAN SISWA
A3: Nama | C3: =Sheet1!C15 -> DIMAS ERLANGGA
A4: NIS | C4: =Sheet1!B15 -> 231001290
A5: Kelas | C5: =Sheet1!C4 -> XII - OTKP 1
A6: Jumlah Setoran | C6: =SUM(C12:C376) -> 84000
A7: Jumlah Penarikan | C7: =SUM(D12:D376) -> 0
A8: Saldo Tabungan | C8: =SUM(C6-C7) -> 84000
A11: NO | B11: TANGGAL | C11: SETORAN | D11: PENARIKAN | E11: SALDO
A12: =IF(B12<>"",ROW()-11,"") -> 1 | B12: 45852 | C12: 59000 | E12: =IF(B12<>"",C12-D12,"") -> 59000 | I12: 1
A13: =IF(B13<>"",ROW()-11,"") -> 2 | B13: 45853 | E13: =IF(B13<>"",E12+C13-D13,"") -> 59000 | I13: 2
A14: =IF(B14<>"",ROW()-11,"") -> 3 | B14: 45854 | E14: =IF(B14<>"",E13+C14-D14,"") -> 59000 | I14: 3
A15: =IF(B15<>"",ROW()-11,"") -> 4 | B15: 45855 | E15: =IF(B15<>"",E14+C15-D15,"") -> 59000 | I15: 4
A16: =IF(B16<>"",ROW()-11,"") -> 5 | B16: 45856 | E16: =IF(B16<>"",E15+C16-D16,"") -> 59000 | I16: 5
A17: =IF(B17<>"",ROW()-11,"") -> 6 | B17: 45857 | E17: =IF(B17<>"",E16+C17-D17,"") -> 59000 | I17: 6
A18: =IF(B18<>"",ROW()-11,"") -> 7 | B18: 45858 | E18: =IF(B18<>"",E17+C18-D18,"") -> 59000 | I18: 7
A19: =IF(B19<>"",ROW()-11,"") -> 8 | B19: 45859 | E19: =IF(B19<>"",E18+C19-D19,"") -> 59000 | I19: 8
A20: =IF(B20<>"",ROW()-11,"") -> 9 | B20: 45860 | E20: =IF(B20<>"",E19+C20-D20,"") -> 59000 | I20: 9
A21: =IF(B21<>"",ROW()-11,"") -> 10 | B21: 45861 | E21: =IF(B21<>"",E20+C21-D21,"") -> 59000 | I21: 10
A22: =IF(B22<>"",ROW()-11,"") -> 11 | B22: 45862 | C22: 5000 | E22: =IF(B22<>"",E21+C22-D22,"") -> 64000 | I22: 11
A23: =IF(B23<>"",ROW()-11,"") -> 12 | B23: 45863 | E23: =IF(B23<>"",E22+C23-D23,"") -> 64000 | I23: 12
A24: =IF(B24<>"",ROW()-11,"") -> 13 | B24: 45864 | E24: =IF(B24<>"",E23+C24-D24,"") -> 64000 | I24: 13
A25: =IF(B25<>"",ROW()-11,"") -> 14 | B25: 45865 | E25: =IF(B25<>"",E24+C25-D25,"") -> 64000 | I25: 14
A26: =IF(B26<>"",ROW()-11,"") -> 15 | B26: 45866 | C26: 10000 | E26: =IF(B26<>"",E25+C26-D26,"") -> 74000 | I26: 15
A27: =IF(B27<>"",ROW()-11,"") -> 16 | B27: 45867 | C27: 5000 | E27: =IF(B27<>"",E26+C27-D27,"") -> 79000 | I27: 16
A28: =IF(B28<>"",ROW()-11,"") -> 17 | B28: 45868 | E28: =IF(B28<>"",E27+C28-D28,"") -> 79000 | I28: 17
A29: =IF(B29<>"",ROW()-11,"") -> 18 | B29: 45869 | E29: =IF(B29<>"",E28+C29-D29,"") -> 79000 | I29: 18
A30: =IF(B30<>"",ROW()-11,"") -> 19 | B30: 45870 | E30: =IF(B30<>"",E29+C30-D30,"") -> 79000 | I30: 19
A31: =IF(B31<>"",ROW()-11,"") -> 20 | B31: 45871 | E31: =IF(B31<>"",E30+C31-D31,"") -> 79000 | I31: 20
A32: =IF(B32<>"",ROW()-11,"") -> 21 | B32: 45872 | E32: =IF(B32<>"",E31+C32-D32,"") -> 79000 | I32: 21
A33: =IF(B33<>"",ROW()-11,"") -> 22 | B33: 45873 | E33: =IF(B33<>"",E32+C33-D33,"") -> 79000 | I33: 22
A34: =IF(B34<>"",ROW()-11,"") -> 23 | B34: 45874 | E34: =IF(B34<>"",E33+C34-D34,"") -> 79000 | I34: 23
A35: =IF(B35<>"",ROW()-11,"") -> 24 | B35: 45875 | E35: =IF(B35<>"",E34+C35-D35,"") -> 79000 | I35: 24
A36: =IF(B36<>"",ROW()-11,"") -> 25 | B36: 45876 | E36: =IF(B36<>"",E35+C36-D36,"") -> 79000 | I36: 25
A37: =IF(B37<>"",ROW()-11,"") -> 26 | B37: 45877 | E37: =IF(B37<>"",E36+C37-D37,"") -> 79000 | I37: 26
A38: =IF(B38<>"",ROW()-11,"") -> 27 | B38: 45878 | E38: =IF(B38<>"",E37+C38-D38,"") -> 79000 | I38: 27
A39: =IF(B39<>"",ROW()-11,"") -> 28 | B39: 45879 | E39: =IF(B39<>"",E38+C39-D39,"") -> 79000 | I39: 28
... A77: =IF(B77<>"",ROW()-11,"") -> 66 | B77: 45917 | E77: =IF(B77<>"",E76+C77-D77,"") -> 79000 | I77: 66
A78: =IF(B78<>"",ROW()-11,"") -> 67 | B78: 45918 | C78: 5000 | E78: =IF(B78<>"",E77+C78-D78,"") -> 84000 | I78: 67
A79: =IF(B79<>"",ROW()-11,"") -> 68 | B79: 45919 | E79: =IF(B79<>"",E78+C79-D79,"") -> 84000 | I79: 68
A80: =IF(B80<>"",ROW()-11,"") -> 69 | B80: 45920 | E80: =IF(B80<>"",E79+C80-D80,"") -> 84000 | I80: 69
...

Sheet 8
A1: BUKU TABUNGAN SISWA
A3: Nama | C3: =Sheet1!C16 -> DINI ANJANI NUR AENI
A4: NIS | C4: =Sheet1!B16 -> 231001291
A5: Kelas | C5: =Sheet1!C4 -> XII - OTKP 1
A6: Jumlah Setoran | C6: =SUM(C12:C376) -> 38000
A7: Jumlah Penarikan | C7: =SUM(D12:D376) -> 0
A8: Saldo Tabungan | C8: =SUM(C6-C7) -> 38000
A11: NO | B11: TANGGAL | C11: SETORAN | D11: PENARIKAN | E11: SALDO
A12: =IF(B12<>"",ROW()-11,"") -> 1 | B12: 45852 | C12: 29000 | E12: =IF(B12<>"",C12-D12,"") -> 29000 | I12: 1
A13: =IF(B13<>"",ROW()-11,"") -> 2 | B13: 45853 | E13: =IF(B13<>"",E12+C13-D13,"") -> 29000 | I13: 2
A14: =IF(B14<>"",ROW()-11,"") -> 3 | B14: 45854 | E14: =IF(B14<>"",E13+C14-D14,"") -> 29000 | I14: 3
A15: =IF(B15<>"",ROW()-11,"") -> 4 | B15: 45855 | E15: =IF(B15<>"",E14+C15-D15,"") -> 29000 | I15: 4
A16: =IF(B16<>"",ROW()-11,"") -> 5 | B16: 45856 | E16: =IF(B16<>"",E15+C16-D16,"") -> 29000 | I16: 5
A17: =IF(B17<>"",ROW()-11,"") -> 6 | B17: 45857 | E17: =IF(B17<>"",E16+C17-D17,"") -> 29000 | I17: 6
A18: =IF(B18<>"",ROW()-11,"") -> 7 | B18: 45858 | E18: =IF(B18<>"",E17+C18-D18,"") -> 29000 | I18: 7
A19: =IF(B19<>"",ROW()-11,"") -> 8 | B19: 45859 | E19: =IF(B19<>"",E18+C19-D19,"") -> 29000 | I19: 8
A20: =IF(B20<>"",ROW()-11,"") -> 9 | B20: 45860 | E20: =IF(B20<>"",E19+C20-D20,"") -> 29000 | I20: 9
A21: =IF(B21<>"",ROW()-11,"") -> 10 | B21: 45861 | E21: =IF(B21<>"",E20+C21-D21,"") -> 29000 | I21: 10
A22: =IF(B22<>"",ROW()-11,"") -> 11 | B22: 45862 | E22: =IF(B22<>"",E21+C22-D22,"") -> 29000 | I22: 11
A23: =IF(B23<>"",ROW()-11,"") -> 12 | B23: 45863 | E23: =IF(B23<>"",E22+C23-D23,"") -> 29000 | I23: 12
A24: =IF(B24<>"",ROW()-11,"") -> 13 | B24: 45864 | E24: =IF(B24<>"",E23+C24-D24,"") -> 29000 | I24: 13
... A32: =IF(B32<>"",ROW()-11,"") -> 21 | B32: 45872 | E32: =IF(B32<>"",E31+C32-D32,"") -> 29000 | I32: 21
A33: =IF(B33<>"",ROW()-11,"") -> 22 | B33: 45873 | C33: 2000 | E33: =IF(B33<>"",E32+C33-D33,"") -> 31000 | I33: 22
A34: =IF(B34<>"",ROW()-11,"") -> 23 | B34: 45874 | E34: =IF(B34<>"",E33+C34-D34,"") -> 31000 | I34: 23
A35: =IF(B35<>"",ROW()-11,"") -> 24 | B35: 45875 | E35: =IF(B35<>"",E34+C35-D35,"") -> 31000 | I35: 24
A36: =IF(B36<>"",ROW()-11,"") -> 25 | B36: 45876 | E36: =IF(B36<>"",E35+C36-D36,"") -> 31000 | I36: 25
A37: =IF(B37<>"",ROW()-11,"") -> 26 | B37: 45877 | E37: =IF(B37<>"",E36+C37-D37,"") -> 31000 | I37: 26
A38: =IF(B38<>"",ROW()-11,"") -> 27 | B38: 45878 | E38: =IF(B38<>"",E37+C38-D38,"") -> 31000 | I38: 27
A39: =IF(B39<>"",ROW()-11,"") -> 28 | B39: 45879 | E39: =IF(B39<>"",E38+C39-D39,"") -> 31000 | I39: 28
A40: =IF(B40<>"",ROW()-11,"") -> 29 | B40: 45880 | E40: =IF(B40<>"",E39+C40-D40,"") -> 31000 | I40: 29
A41: =IF(B41<>"",ROW()-11,"") -> 30 | B41: 45881 | E41: =IF(B41<>"",E40+C41-D41,"") -> 31000 | I41: 30
A42: =IF(B42<>"",ROW()-11,"") -> 31 | B42: 45882 | E42: =IF(B42<>"",E41+C42-D42,"") -> 31000 | I42: 31
A43: =IF(B43<>"",ROW()-11,"") -> 32 | B43: 45883 | E43: =IF(B43<>"",E42+C43-D43,"") -> 31000 | I43: 32
A44: =IF(B44<>"",ROW()-11,"") -> 33 | B44: 45884 | E44: =IF(B44<>"",E43+C44-D44,"") -> 31000 | I44: 33
A45: =IF(B45<>"",ROW()-11,"") -> 34 | B45: 45885 | E45: =IF(B45<>"",E44+C45-D45,"") -> 31000 | I45: 34
... A90: =IF(B90<>"",ROW()-11,"") -> 79 | B90: 45930 | E90: =IF(B90<>"",E89+C90-D90,"") -> 31000 | I90: 79
A91: =IF(B91<>"",ROW()-11,"") -> 80 | B91: 45931 | C91: 5000 | E91: =IF(B91<>"",E90+C91-D91,"") -> 36000 | I91: 80
A92: =IF(B92<>"",ROW()-11,"") -> 81 | B92: 45932 | C92: 2000 | E92: =IF(B92<>"",E91+C92-D92,"") -> 38000 | I92: 81
A93: =IF(B93<>"",ROW()-11,"") -> 82 | B93: 45933 | E93: =IF(B93<>"",E92+C93-D93,"") -> 38000 | I93: 82
A94: =IF(B94<>"",ROW()-11,"") -> 83 | B94: 45934 | E94: =IF(B94<>"",E93+C94-D94,"") -> 38000 | I94: 83
...

Sheet 9
A1: BUKU TABUNGAN SISWA
A3: Nama | C3: =Sheet1!C17 -> FITRYA
A4: NIS | C4: =Sheet1!B17 -> 231001292
A5: Kelas | C5: =Sheet1!C4 -> XII - OTKP 1
A6: Jumlah Setoran | C6: =SUM(C12:C376) -> 109000
A7: Jumlah Penarikan | C7: =SUM(D12:D376) -> 0
A8: Saldo Tabungan | C8: =SUM(C6-C7) -> 109000
A11: NO | B11: TANGGAL | C11: SETORAN | D11: PENARIKAN | E11: SALDO
A12: =IF(B12<>"",ROW()-11,"") -> 1 | B12: 45852 | E12: =IF(B12<>"",C12-D12,"") -> 0 | I12: 1
A13: =IF(B13<>"",ROW()-11,"") -> 2 | B13: 45853 | E13: =IF(B13<>"",E12+C13-D13,"") -> 0 | I13: 2
A14: =IF(B14<>"",ROW()-11,"") -> 3 | B14: 45854 | E14: =IF(B14<>"",E13+C14-D14,"") -> 0 | I14: 3
A15: =IF(B15<>"",ROW()-11,"") -> 4 | B15: 45855 | E15: =IF(B15<>"",E14+C15-D15,"") -> 0 | I15: 4
A16: =IF(B16<>"",ROW()-11,"") -> 5 | B16: 45856 | E16: =IF(B16<>"",E15+C16-D16,"") -> 0 | I16: 5
A17: =IF(B17<>"",ROW()-11,"") -> 6 | B17: 45857 | E17: =IF(B17<>"",E16+C17-D17,"") -> 0 | I17: 6
A18: =IF(B18<>"",ROW()-11,"") -> 7 | B18: 45858 | E18: =IF(B18<>"",E17+C18-D18,"") -> 0 | I18: 7
A19: =IF(B19<>"",ROW()-11,"") -> 8 | B19: 45859 | E19: =IF(B19<>"",E18+C19-D19,"") -> 0 | I19: 8
A20: =IF(B20<>"",ROW()-11,"") -> 9 | B20: 45860 | E20: =IF(B20<>"",E19+C20-D20,"") -> 0 | I20: 9
A21: =IF(B21<>"",ROW()-11,"") -> 10 | B21: 45861 | E21: =IF(B21<>"",E20+C21-D21,"") -> 0 | I21: 10
A22: =IF(B22<>"",ROW()-11,"") -> 11 | B22: 45862 | E22: =IF(B22<>"",E21+C22-D22,"") -> 0 | I22: 11
A23: =IF(B23<>"",ROW()-11,"") -> 12 | B23: 45863 | E23: =IF(B23<>"",E22+C23-D23,"") -> 0 | I23: 12
A24: =IF(B24<>"",ROW()-11,"") -> 13 | B24: 45864 | E24: =IF(B24<>"",E23+C24-D24,"") -> 0 | I24: 13
... A26: =IF(B26<>"",ROW()-11,"") -> 15 | B26: 45866 | E26: =IF(B26<>"",E25+C26-D26,"") -> 0 | I26: 15
A27: =IF(B27<>"",ROW()-11,"") -> 16 | B27: 45867 | C27: 50000 | E27: =IF(B27<>"",E26+C27-D27,"") -> 50000 | I27: 16
A28: =IF(B28<>"",ROW()-11,"") -> 17 | B28: 45868 | C28: 7000 | E28: =IF(B28<>"",E27+C28-D28,"") -> 57000 | I28: 17
A29: =IF(B29<>"",ROW()-11,"") -> 18 | B29: 45869 | C29: 10000 | E29: =IF(B29<>"",E28+C29-D29,"") -> 67000 | I29: 18
A30: =IF(B30<>"",ROW()-11,"") -> 19 | B30: 45870 | E30: =IF(B30<>"",E29+C30-D30,"") -> 67000 | I30: 19
A31: =IF(B31<>"",ROW()-11,"") -> 20 | B31: 45871 | E31: =IF(B31<>"",E30+C31-D31,"") -> 67000 | I31: 20
A32: =IF(B32<>"",ROW()-11,"") -> 21 | B32: 45872 | E32: =IF(B32<>"",E31+C32-D32,"") -> 67000 | I32: 21
A33: =IF(B33<>"",ROW()-11,"") -> 22 | B33: 45873 | C33: 2000 | E33: =IF(B33<>"",E32+C33-D33,"") -> 69000 | I33: 22
A34: =IF(B34<>"",ROW()-11,"") -> 23 | B34: 45874 | E34: =IF(B34<>"",E33+C34-D34,"") -> 69000 | I34: 23
A35: =IF(B35<>"",ROW()-11,"") -> 24 | B35: 45875 | C35: 2000 | E35: =IF(B35<>"",E34+C35-D35,"") -> 71000 | I35: 24
A36: =IF(B36<>"",ROW()-11,"") -> 25 | B36: 45876 | C36: 2000 | E36: =IF(B36<>"",E35+C36-D36,"") -> 73000 | I36: 25
A37: =IF(B37<>"",ROW()-11,"") -> 26 | B37: 45877 | E37: =IF(B37<>"",E36+C37-D37,"") -> 73000 | I37: 26
A38: =IF(B38<>"",ROW()-11,"") -> 27 | B38: 45878 | E38: =IF(B38<>"",E37+C38-D38,"") -> 73000 | I38: 27
A39: =IF(B39<>"",ROW()-11,"") -> 28 | B39: 45879 | E39: =IF(B39<>"",E38+C39-D39,"") -> 73000 | I39: 28
A40: =IF(B40<>"",ROW()-11,"") -> 29 | B40: 45880 | C40: 2000 | E40: =IF(B40<>"",E39+C40-D40,"") -> 75000 | I40: 29
A41: =IF(B41<>"",ROW()-11,"") -> 30 | B41: 45881 | C41: 2000 | E41: =IF(B41<>"",E40+C41-D41,"") -> 77000 | I41: 30
A42: =IF(B42<>"",ROW()-11,"") -> 31 | B42: 45882 | E42: =IF(B42<>"",E41+C42-D42,"") -> 77000 | I42: 31
A43: =IF(B43<>"",ROW()-11,"") -> 32 | B43: 45883 | C43: 2000 | E43: =IF(B43<>"",E42+C43-D43,"") -> 79000 | I43: 32
A44: =IF(B44<>"",ROW()-11,"") -> 33 | B44: 45884 | C44: 2000 | E44: =IF(B44<>"",E43+C44-D44,"") -> 81000 | I44: 33
...

Sheet 10
A1: BUKU TABUNGAN SISWA
A3: Nama | C3: =Sheet1!C18 -> HALIMATUSSADIAH
A4: NIS | C4: =Sheet1!B18 -> 231001293
A5: Kelas | C5: =Sheet1!C4 -> XII - OTKP 1
A6: Jumlah Setoran | C6: =SUM(C12:C376) -> 132000
A7: Jumlah Penarikan | C7: =SUM(D12:D376) -> 0
A8: Saldo Tabungan | C8: =SUM(C6-C7) -> 132000
A11: NO | B11: TANGGAL | C11: SETORAN | D11: PENARIKAN | E11: SALDO
A12: =IF(B12<>"",ROW()-11,"") -> 1 | B12: 45852 | C12: 94000 | E12: =IF(B12<>"",C12-D12,"") -> 94000 | I12: 1
A13: =IF(B13<>"",ROW()-11,"") -> 2 | B13: 45853 | E13: =IF(B13<>"",E12+C13-D13,"") -> 94000 | I13: 2
A14: =IF(B14<>"",ROW()-11,"") -> 3 | B14: 45854 | E14: =IF(B14<>"",E13+C14-D14,"") -> 94000 | I14: 3
A15: =IF(B15<>"",ROW()-11,"") -> 4 | B15: 45855 | E15: =IF(B15<>"",E14+C15-D15,"") -> 94000 | I15: 4
A16: =IF(B16<>"",ROW()-11,"") -> 5 | B16: 45856 | E16: =IF(B16<>"",E15+C16-D16,"") -> 94000 | I16: 5
A17: =IF(B17<>"",ROW()-11,"") -> 6 | B17: 45857 | E17: =IF(B17<>"",E16+C17-D17,"") -> 94000 | I17: 6
A18: =IF(B18<>"",ROW()-11,"") -> 7 | B18: 45858 | E18: =IF(B18<>"",E17+C18-D18,"") -> 94000 | I18: 7
A19: =IF(B19<>"",ROW()-11,"") -> 8 | B19: 45859 | E19: =IF(B19<>"",E18+C19-D19,"") -> 94000 | I19: 8
A20: =IF(B20<>"",ROW()-11,"") -> 9 | B20: 45860 | E20: =IF(B20<>"",E19+C20-D20,"") -> 94000 | I20: 9
A21: =IF(B21<>"",ROW()-11,"") -> 10 | B21: 45861 | C21: 5000 | E21: =IF(B21<>"",E20+C21-D21,"") -> 99000 | I21: 10
A22: =IF(B22<>"",ROW()-11,"") -> 11 | B22: 45862 | C22: 5000 | E22: =IF(B22<>"",E21+C22-D22,"") -> 104000 | I22: 11
A23: =IF(B23<>"",ROW()-11,"") -> 12 | B23: 45863 | E23: =IF(B23<>"",E22+C23-D23,"") -> 104000 | I23: 12
A24: =IF(B24<>"",ROW()-11,"") -> 13 | B24: 45864 | E24: =IF(B24<>"",E23+C24-D24,"") -> 104000 | I24: 13
A25: =IF(B25<>"",ROW()-11,"") -> 14 | B25: 45865 | E25: =IF(B25<>"",E24+C25-D25,"") -> 104000 | I25: 14
A26: =IF(B26<>"",ROW()-11,"") -> 15 | B26: 45866 | E26: =IF(B26<>"",E25+C26-D26,"") -> 104000 | I26: 15
A27: =IF(B27<>"",ROW()-11,"") -> 16 | B27: 45867 | E27: =IF(B27<>"",E26+C27-D27,"") -> 104000 | I27: 16
A28: =IF(B28<>"",ROW()-11,"") -> 17 | B28: 45868 | E28: =IF(B28<>"",E27+C28-D28,"") -> 104000 | I28: 17
A29: =IF(B29<>"",ROW()-11,"") -> 18 | B29: 45869 | E29: =IF(B29<>"",E28+C29-D29,"") -> 104000 | I29: 18
A30: =IF(B30<>"",ROW()-11,"") -> 19 | B30: 45870 | E30: =IF(B30<>"",E29+C30-D30,"") -> 104000 | I30: 19
A31: =IF(B31<>"",ROW()-11,"") -> 20 | B31: 45871 | E31: =IF(B31<>"",E30+C31-D31,"") -> 104000 | I31: 20
A32: =IF(B32<>"",ROW()-11,"") -> 21 | B32: 45872 | E32: =IF(B32<>"",E31+C32-D32,"") -> 104000 | I32: 21
A33: =IF(B33<>"",ROW()-11,"") -> 22 | B33: 45873 | E33: =IF(B33<>"",E32+C33-D33,"") -> 104000 | I33: 22
A34: =IF(B34<>"",ROW()-11,"") -> 23 | B34: 45874 | E34: =IF(B34<>"",E33+C34-D34,"") -> 104000 | I34: 23
... A53: =IF(B53<>"",ROW()-11,"") -> 42 | B53: 45893 | E53: =IF(B53<>"",E52+C53-D53,"") -> 104000 | I53: 42
A54: =IF(B54<>"",ROW()-11,"") -> 43 | B54: 45894 | C54: 5000 | E54: =IF(B54<>"",E53+C54-D54,"") -> 109000 | I54: 43
A55: =IF(B55<>"",ROW()-11,"") -> 44 | B55: 45895 | E55: =IF(B55<>"",E54+C55-D55,"") -> 109000 | I55: 44
A56: =IF(B56<>"",ROW()-11,"") -> 45 | B56: 45896 | E56: =IF(B56<>"",E55+C56-D56,"") -> 109000 | I56: 45
A57: =IF(B57<>"",ROW()-11,"") -> 46 | B57: 45897 | C57: 4000 | E57: =IF(B57<>"",E56+C57-D57,"") -> 113000 | I57: 46
A58: =IF(B58<>"",ROW()-11,"") -> 47 | B58: 45898 | E58: =IF(B58<>"",E57+C58-D58,"") -> 113000 | I58: 47
A59: =IF(B59<>"",ROW()-11,"") -> 48 | B59: 45899 | E59: =IF(B59<>"",E58+C59-D59,"") -> 113000 | I59: 48
A60: =IF(B60<>"",ROW()-11,"") -> 49 | B60: 45900 | E60: =IF(B60<>"",E59+C60-D60,"") -> 113000 | I60: 49
A61: =IF(B61<>"",ROW()-11,"") -> 50 | B61: 45901 | E61: =IF(B61<>"",E60+C61-D61,"") -> 113000 | I61: 50
...

Sheet 11
A1: BUKU TABUNGAN SISWA
A3: Nama | C3: =Sheet1!C19 -> IKSAN NUGRAHA
A4: NIS | C4: =Sheet1!B19 -> 231001294
A5: Kelas | C5: =Sheet1!C4 -> XII - OTKP 1
A6: Jumlah Setoran | C6: =SUM(C12:C376) -> 18000
A7: Jumlah Penarikan | C7: =SUM(D12:D376) -> 0
A8: Saldo Tabungan | C8: =SUM(C6-C7) -> 18000
A11: NO | B11: TANGGAL | C11: SETORAN | D11: PENARIKAN | E11: SALDO
A12: =IF(B12<>"",ROW()-11,"") -> 1 | B12: 45852 | C12: 18000 | E12: =IF(B12<>"",C12-D12,"") -> 18000 | I12: 1
A13: =IF(B13<>"",ROW()-11,"") -> 2 | B13: 45853 | E13: =IF(B13<>"",E12+C13-D13,"") -> 18000 | I13: 2
A14: =IF(B14<>"",ROW()-11,"") -> 3 | B14: 45854 | E14: =IF(B14<>"",E13+C14-D14,"") -> 18000 | I14: 3
A15: =IF(B15<>"",ROW()-11,"") -> 4 | B15: 45855 | E15: =IF(B15<>"",E14+C15-D15,"") -> 18000 | I15: 4
A16: =IF(B16<>"",ROW()-11,"") -> 5 | B16: 45856 | E16: =IF(B16<>"",E15+C16-D16,"") -> 18000 | I16: 5
A17: =IF(B17<>"",ROW()-11,"") -> 6 | B17: 45857 | E17: =IF(B17<>"",E16+C17-D17,"") -> 18000 | I17: 6
A18: =IF(B18<>"",ROW()-11,"") -> 7 | B18: 45858 | E18: =IF(B18<>"",E17+C18-D18,"") -> 18000 | I18: 7
A19: =IF(B19<>"",ROW()-11,"") -> 8 | B19: 45859 | E19: =IF(B19<>"",E18+C19-D19,"") -> 18000 | I19: 8
A20: =IF(B20<>"",ROW()-11,"") -> 9 | B20: 45860 | E20: =IF(B20<>"",E19+C20-D20,"") -> 18000 | I20: 9
A21: =IF(B21<>"",ROW()-11,"") -> 10 | B21: 45861 | E21: =IF(B21<>"",E20+C21-D21,"") -> 18000 | I21: 10
A22: =IF(B22<>"",ROW()-11,"") -> 11 | B22: 45862 | E22: =IF(B22<>"",E21+C22-D22,"") -> 18000 | I22: 11
A23: =IF(B23<>"",ROW()-11,"") -> 12 | B23: 45863 | E23: =IF(B23<>"",E22+C23-D23,"") -> 18000 | I23: 12
A24: =IF(B24<>"",ROW()-11,"") -> 13 | B24: 45864 | E24: =IF(B24<>"",E23+C24-D24,"") -> 18000 | I24: 13
... A376: =IF(B376<>"",ROW()-11,"") -> 365 | B376: 46216 | E376: =IF(B376<>"",E375+C376-D376,"") -> 18000 | I376: 365

Sheet 12
A1: BUKU TABUNGAN SISWA
A3: Nama | C3: =Sheet1!C20 -> JULIA
A4: NIS | C4: =Sheet1!B20 -> 231001295
A5: Kelas | C5: =Sheet1!C4 -> XII - OTKP 1
A6: Jumlah Setoran | C6: =SUM(C12:C376) -> 100000
A7: Jumlah Penarikan | C7: =SUM(D12:D376) -> 100000
A8: Saldo Tabungan | C8: =SUM(C6-C7) -> 0
A11: NO | B11: TANGGAL | C11: SETORAN | D11: PENARIKAN | E11: SALDO
A12: =IF(B12<>"",ROW()-11,"") -> 1 | B12: 45852 | C12: 20000 | E12: =IF(B12<>"",C12-D12,"") -> 20000 | I12: 1
A13: =IF(B13<>"",ROW()-11,"") -> 2 | B13: 45853 | E13: =IF(B13<>"",E12+C13-D13,"") -> 20000 | I13: 2
A14: =IF(B14<>"",ROW()-11,"") -> 3 | B14: 45854 | E14: =IF(B14<>"",E13+C14-D14,"") -> 20000 | I14: 3
A15: =IF(B15<>"",ROW()-11,"") -> 4 | B15: 45855 | E15: =IF(B15<>"",E14+C15-D15,"") -> 20000 | I15: 4
A16: =IF(B16<>"",ROW()-11,"") -> 5 | B16: 45856 | E16: =IF(B16<>"",E15+C16-D16,"") -> 20000 | I16: 5
A17: =IF(B17<>"",ROW()-11,"") -> 6 | B17: 45857 | E17: =IF(B17<>"",E16+C17-D17,"") -> 20000 | I17: 6
A18: =IF(B18<>"",ROW()-11,"") -> 7 | B18: 45858 | E18: =IF(B18<>"",E17+C18-D18,"") -> 20000 | I18: 7
A19: =IF(B19<>"",ROW()-11,"") -> 8 | B19: 45859 | E19: =IF(B19<>"",E18+C19-D19,"") -> 20000 | I19: 8
A20: =IF(B20<>"",ROW()-11,"") -> 9 | B20: 45860 | E20: =IF(B20<>"",E19+C20-D20,"") -> 20000 | I20: 9
A21: =IF(B21<>"",ROW()-11,"") -> 10 | B21: 45861 | C21: 2000 | E21: =IF(B21<>"",E20+C21-D21,"") -> 22000 | I21: 10
A22: =IF(B22<>"",ROW()-11,"") -> 11 | B22: 45862 | E22: =IF(B22<>"",E21+C22-D22,"") -> 22000 | I22: 11
A23: =IF(B23<>"",ROW()-11,"") -> 12 | B23: 45863 | E23: =IF(B23<>"",E22+C23-D23,"") -> 22000 | I23: 12
A24: =IF(B24<>"",ROW()-11,"") -> 13 | B24: 45864 | E24: =IF(B24<>"",E23+C24-D24,"") -> 22000 | I24: 13
A25: =IF(B25<>"",ROW()-11,"") -> 14 | B25: 45865 | E25: =IF(B25<>"",E24+C25-D25,"") -> 22000 | I25: 14
A26: =IF(B26<>"",ROW()-11,"") -> 15 | B26: 45866 | C26: 5000 | E26: =IF(B26<>"",E25+C26-D26,"") -> 27000 | I26: 15
A27: =IF(B27<>"",ROW()-11,"") -> 16 | B27: 45867 | C27: 3000 | E27: =IF(B27<>"",E26+C27-D27,"") -> 30000 | I27: 16
A28: =IF(B28<>"",ROW()-11,"") -> 17 | B28: 45868 | C28: 20000 | E28: =IF(B28<>"",E27+C28-D28,"") -> 50000 | I28: 17
A29: =IF(B29<>"",ROW()-11,"") -> 18 | B29: 45869 | E29: =IF(B29<>"",E28+C29-D29,"") -> 50000 | I29: 18
A30: =IF(B30<>"",ROW()-11,"") -> 19 | B30: 45870 | E30: =IF(B30<>"",E29+C30-D30,"") -> 50000 | I30: 19
A31: =IF(B31<>"",ROW()-11,"") -> 20 | B31: 45871 | E31: =IF(B31<>"",E30+C31-D31,"") -> 50000 | I31: 20
A32: =IF(B32<>"",ROW()-11,"") -> 21 | B32: 45872 | E32: =IF(B32<>"",E31+C32-D32,"") -> 50000 | I32: 21
A33: =IF(B33<>"",ROW()-11,"") -> 22 | B33: 45873 | E33: =IF(B33<>"",E32+C33-D33,"") -> 50000 | I33: 22
A34: =IF(B34<>"",ROW()-11,"") -> 23 | B34: 45874 | E34: =IF(B34<>"",E33+C34-D34,"") -> 50000 | I34: 23
A35: =IF(B35<>"",ROW()-11,"") -> 24 | B35: 45875 | E35: =IF(B35<>"",E34+C35-D35,"") -> 50000 | I35: 24
A36: =IF(B36<>"",ROW()-11,"") -> 25 | B36: 45876 | E36: =IF(B36<>"",E35+C36-D36,"") -> 50000 | I36: 25
A37: =IF(B37<>"",ROW()-11,"") -> 26 | B37: 45877 | E37: =IF(B37<>"",E36+C37-D37,"") -> 50000 | I37: 26
A38: =IF(B38<>"",ROW()-11,"") -> 27 | B38: 45878 | E38: =IF(B38<>"",E37+C38-D38,"") -> 50000 | I38: 27
A39: =IF(B39<>"",ROW()-11,"") -> 28 | B39: 45879 | E39: =IF(B39<>"",E38+C39-D39,"") -> 50000 | I39: 28
A40: =IF(B40<>"",ROW()-11,"") -> 29 | B40: 45880 | E40: =IF(B40<>"",E39+C40-D40,"") -> 50000 | I40: 29
... A42: =IF(B42<>"",ROW()-11,"") -> 31 | B42: 45882 | E42: =IF(B42<>"",E41+C42-D42,"") -> 50000 | I42: 31
A43: =IF(B43<>"",ROW()-11,"") -> 32 | B43: 45883 | C43: 50000 | E43: =IF(B43<>"",E42+C43-D43,"") -> 100000 | I43: 32
A44: =IF(B44<>"",ROW()-11,"") -> 33 | B44: 45884 | E44: =IF(B44<>"",E43+C44-D44,"") -> 100000 | I44: 33
...

Sheet 13
A1: BUKU TABUNGAN SISWA
A3: Nama | C3: =Sheet1!C21 -> KANANTI MAHARDINI
A4: NIS | C4: =Sheet1!B21 -> 231001296
A5: Kelas | C5: =Sheet1!C4 -> XII - OTKP 1
A6: Jumlah Setoran | C6: =SUM(C12:C376) -> 64000
A7: Jumlah Penarikan | C7: =SUM(D12:D376) -> 50000
A8: Saldo Tabungan | C8: =SUM(C6-C7) -> 14000
A11: NO | B11: TANGGAL | C11: SETORAN | D11: PENARIKAN | E11: SALDO
A12: =IF(B12<>"",ROW()-11,"") -> 1 | B12: 45852 | C12: 53000 | E12: =IF(B12<>"",C12-D12,"") -> 53000 | I12: 1
A13: =IF(B13<>"",ROW()-11,"") -> 2 | B13: 45853 | E13: =IF(B13<>"",E12+C13-D13,"") -> 53000 | I13: 2
A14: =IF(B14<>"",ROW()-11,"") -> 3 | B14: 45854 | E14: =IF(B14<>"",E13+C14-D14,"") -> 53000 | I14: 3
A15: =IF(B15<>"",ROW()-11,"") -> 4 | B15: 45855 | E15: =IF(B15<>"",E14+C15-D15,"") -> 53000 | I15: 4
A16: =IF(B16<>"",ROW()-11,"") -> 5 | B16: 45856 | E16: =IF(B16<>"",E15+C16-D16,"") -> 53000 | I16: 5
A17: =IF(B17<>"",ROW()-11,"") -> 6 | B17: 45857 | E17: =IF(B17<>"",E16+C17-D17,"") -> 53000 | I17: 6
A18: =IF(B18<>"",ROW()-11,"") -> 7 | B18: 45858 | E18: =IF(B18<>"",E17+C18-D18,"") -> 53000 | I18: 7
A19: =IF(B19<>"",ROW()-11,"") -> 8 | B19: 45859 | E19: =IF(B19<>"",E18+C19-D19,"") -> 53000 | I19: 8
A20: =IF(B20<>"",ROW()-11,"") -> 9 | B20: 45860 | E20: =IF(B20<>"",E19+C20-D20,"") -> 53000 | I20: 9
A21: =IF(B21<>"",ROW()-11,"") -> 10 | B21: 45861 | C21: 2000 | E21: =IF(B21<>"",E20+C21-D21,"") -> 55000 | I21: 10
A22: =IF(B22<>"",ROW()-11,"") -> 11 | B22: 45862 | E22: =IF(B22<>"",E21+C22-D22,"") -> 55000 | I22: 11
A23: =IF(B23<>"",ROW()-11,"") -> 12 | B23: 45863 | E23: =IF(B23<>"",E22+C23-D23,"") -> 55000 | I23: 12
A24: =IF(B24<>"",ROW()-11,"") -> 13 | B24: 45864 | E24: =IF(B24<>"",E23+C24-D24,"") -> 55000 | I24: 13
A25: =IF(B25<>"",ROW()-11,"") -> 14 | B25: 45865 | E25: =IF(B25<>"",E24+C25-D25,"") -> 55000 | I25: 14
A26: =IF(B26<>"",ROW()-11,"") -> 15 | B26: 45866 | E26: =IF(B26<>"",E25+C26-D26,"") -> 55000 | I26: 15
A27: =IF(B27<>"",ROW()-11,"") -> 16 | B27: 45867 | E27: =IF(B27<>"",E26+C27-D27,"") -> 55000 | I27: 16
A28: =IF(B28<>"",ROW()-11,"") -> 17 | B28: 45868 | E28: =IF(B28<>"",E27+C28-D28,"") -> 55000 | I28: 17
A29: =IF(B29<>"",ROW()-11,"") -> 18 | B29: 45869 | E29: =IF(B29<>"",E28+C29-D29,"") -> 55000 | I29: 18
A30: =IF(B30<>"",ROW()-11,"") -> 19 | B30: 45870 | E30: =IF(B30<>"",E29+C30-D30,"") -> 55000 | I30: 19
A31: =IF(B31<>"",ROW()-11,"") -> 20 | B31: 45871 | E31: =IF(B31<>"",E30+C31-D31,"") -> 55000 | I31: 20
A32: =IF(B32<>"",ROW()-11,"") -> 21 | B32: 45872 | E32: =IF(B32<>"",E31+C32-D32,"") -> 55000 | I32: 21
A33: =IF(B33<>"",ROW()-11,"") -> 22 | B33: 45873 | C33: 2000 | E33: =IF(B33<>"",E32+C33-D33,"") -> 57000 | I33: 22
A34: =IF(B34<>"",ROW()-11,"") -> 23 | B34: 45874 | E34: =IF(B34<>"",E33+C34-D34,"") -> 57000 | I34: 23
A35: =IF(B35<>"",ROW()-11,"") -> 24 | B35: 45875 | E35: =IF(B35<>"",E34+C35-D35,"") -> 57000 | I35: 24
A36: =IF(B36<>"",ROW()-11,"") -> 25 | B36: 45876 | E36: =IF(B36<>"",E35+C36-D36,"") -> 57000 | I36: 25
A37: =IF(B37<>"",ROW()-11,"") -> 26 | B37: 45877 | E37: =IF(B37<>"",E36+C37-D37,"") -> 57000 | I37: 26
A38: =IF(B38<>"",ROW()-11,"") -> 27 | B38: 45878 | E38: =IF(B38<>"",E37+C38-D38,"") -> 57000 | I38: 27
A39: =IF(B39<>"",ROW()-11,"") -> 28 | B39: 45879 | E39: =IF(B39<>"",E38+C39-D39,"") -> 57000 | I39: 28
A40: =IF(B40<>"",ROW()-11,"") -> 29 | B40: 45880 | E40: =IF(B40<>"",E39+C40-D40,"") -> 57000 | I40: 29
A41: =IF(B41<>"",ROW()-11,"") -> 30 | B41: 45881 | E41: =IF(B41<>"",E40+C41-D41,"") -> 57000 | I41: 30
A42: =IF(B42<>"",ROW()-11,"") -> 31 | B42: 45882 | E42: =IF(B42<>"",E41+C42-D42,"") -> 57000 | I42: 31
A43: =IF(B43<>"",ROW()-11,"") -> 32 | B43: 45883 | E43: =IF(B43<>"",E42+C43-D43,"") -> 57000 | I43: 32
...

Sheet 14
A1: BUKU TABUNGAN SISWA
A3: Nama | C3: =Sheet1!C22 -> M. IRWAN RUHIANSYAH
A4: NIS | C4: =Sheet1!B22 -> 231001299
A5: Kelas | C5: =Sheet1!C4 -> XII - OTKP 1
A6: Jumlah Setoran | C6: =SUM(C12:C376) -> 150000
A7: Jumlah Penarikan | C7: =SUM(D12:D376) -> 15000
A8: Saldo Tabungan | C8: =SUM(C6-C7) -> 135000
A11: NO | B11: TANGGAL | C11: SETORAN | D11: PENARIKAN | E11: SALDO
A12: =IF(B12<>"",ROW()-11,"") -> 1 | B12: 45852 | C12: 90000 | E12: =IF(B12<>"",C12-D12,"") -> 90000 | I12: 1
A13: =IF(B13<>"",ROW()-11,"") -> 2 | B13: 45853 | E13: =IF(B13<>"",E12+C13-D13,"") -> 90000 | I13: 2
A14: =IF(B14<>"",ROW()-11,"") -> 3 | B14: 45854 | E14: =IF(B14<>"",E13+C14-D14,"") -> 90000 | I14: 3
A15: =IF(B15<>"",ROW()-11,"") -> 4 | B15: 45855 | E15: =IF(B15<>"",E14+C15-D15,"") -> 90000 | I15: 4
A16: =IF(B16<>"",ROW()-11,"") -> 5 | B16: 45856 | E16: =IF(B16<>"",E15+C16-D16,"") -> 90000 | I16: 5
A17: =IF(B17<>"",ROW()-11,"") -> 6 | B17: 45857 | E17: =IF(B17<>"",E16+C17-D17,"") -> 90000 | I17: 6
A18: =IF(B18<>"",ROW()-11,"") -> 7 | B18: 45858 | E18: =IF(B18<>"",E17+C18-D18,"") -> 90000 | I18: 7
A19: =IF(B19<>"",ROW()-11,"") -> 8 | B19: 45859 | E19: =IF(B19<>"",E18+C19-D19,"") -> 90000 | I19: 8
A20: =IF(B20<>"",ROW()-11,"") -> 9 | B20: 45860 | E20: =IF(B20<>"",E19+C20-D20,"") -> 90000 | I20: 9
A21: =IF(B21<>"",ROW()-11,"") -> 10 | B21: 45861 | E21: =IF(B21<>"",E20+C21-D21,"") -> 90000 | I21: 10
A22: =IF(B22<>"",ROW()-11,"") -> 11 | B22: 45862 | E22: =IF(B22<>"",E21+C22-D22,"") -> 90000 | I22: 11
A23: =IF(B23<>"",ROW()-11,"") -> 12 | B23: 45863 | E23: =IF(B23<>"",E22+C23-D23,"") -> 90000 | I23: 12
A24: =IF(B24<>"",ROW()-11,"") -> 13 | B24: 45864 | E24: =IF(B24<>"",E23+C24-D24,"") -> 90000 | I24: 13
... A48: =IF(B48<>"",ROW()-11,"") -> 37 | B48: 45888 | E48: =IF(B48<>"",E47+C48-D48,"") -> 90000 | I48: 37
A49: =IF(B49<>"",ROW()-11,"") -> 38 | B49: 45889 | C49: 5000 | E49: =IF(B49<>"",E48+C49-D49,"") -> 95000 | I49: 38
A50: =IF(B50<>"",ROW()-11,"") -> 39 | B50: 45890 | E50: =IF(B50<>"",E49+C50-D50,"") -> 95000 | I50: 39
A51: =IF(B51<>"",ROW()-11,"") -> 40 | B51: 45891 | C51: 5000 | E51: =IF(B51<>"",E50+C51-D51,"") -> 100000 | I51: 40
A52: =IF(B52<>"",ROW()-11,"") -> 41 | B52: 45892 | E52: =IF(B52<>"",E51+C52-D52,"") -> 100000 | I52: 41
A53: =IF(B53<>"",ROW()-11,"") -> 42 | B53: 45893 | E53: =IF(B53<>"",E52+C53-D53,"") -> 100000 | I53: 42
A54: =IF(B54<>"",ROW()-11,"") -> 43 | B54: 45894 | C54: 5000 | E54: =IF(B54<>"",E53+C54-D54,"") -> 105000 | I54: 43
A55: =IF(B55<>"",ROW()-11,"") -> 44 | B55: 45895 | E55: =IF(B55<>"",E54+C55-D55,"") -> 105000 | I55: 44
A56: =IF(B56<>"",ROW()-11,"") -> 45 | B56: 45896 | E56: =IF(B56<>"",E55+C56-D56,"") -> 105000 | I56: 45
A57: =IF(B57<>"",ROW()-11,"") -> 46 | B57: 45897 | E57: =IF(B57<>"",E56+C57-D57,"") -> 105000 | I57: 46
A58: =IF(B58<>"",ROW()-11,"") -> 47 | B58: 45898 | C58: 5000 | E58: =IF(B58<>"",E57+C58-D58,"") -> 110000 | I58: 47
A59: =IF(B59<>"",ROW()-11,"") -> 48 | B59: 45899 | E59: =IF(B59<>"",E58+C59-D59,"") -> 110000 | I59: 48
A60: =IF(B60<>"",ROW()-11,"") -> 49 | B60: 45900 | E60: =IF(B60<>"",E59+C60-D60,"") -> 110000 | I60: 49
A61: =IF(B61<>"",ROW()-11,"") -> 50 | B61: 45901 | C61: 5000 | E61: =IF(B61<>"",E60+C61-D61,"") -> 115000 | I61: 50
A62: =IF(B62<>"",ROW()-11,"") -> 51 | B62: 45902 | E62: =IF(B62<>"",E61+C62-D62,"") -> 115000 | I62: 51
A63: =IF(B63<>"",ROW()-11,"") -> 52 | B63: 45903 | E63: =IF(B63<>"",E62+C63-D63,"") -> 115000 | I63: 52
A64: =IF(B64<>"",ROW()-11,"") -> 53 | B64: 45904 | C64: 5000 | E64: =IF(B64<>"",E63+C64-D64,"") -> 120000 | I64: 53
A65: =IF(B65<>"",ROW()-11,"") -> 54 | B65: 45905 | E65: =IF(B65<>"",E64+C65-D65,"") -> 120000 | I65: 54
A66: =IF(B66<>"",ROW()-11,"") -> 55 | B66: 45906 | E66: =IF(B66<>"",E65+C66-D66,"") -> 120000 | I66: 55
...

Sheet 15
A1: BUKU TABUNGAN SISWA
A3: Nama | C3: =Sheet1!C23 -> MEYLANI SRI RAHAYU
A4: NIS | C4: =Sheet1!B23 -> 231001297
A5: Kelas | C5: =Sheet1!C4 -> XII - OTKP 1
A6: Jumlah Setoran | C6: =SUM(C12:C376) -> 100000
A7: Jumlah Penarikan | C7: =SUM(D12:D376) -> 0
A8: Saldo Tabungan | C8: =SUM(C6-C7) -> 100000
A11: NO | B11: TANGGAL | C11: SETORAN | D11: PENARIKAN | E11: SALDO
A12: =IF(B12<>"",ROW()-11,"") -> 1 | B12: 45852 | C12: 51000 | E12: =IF(B12<>"",C12-D12,"") -> 51000 | I12: 1
A13: =IF(B13<>"",ROW()-11,"") -> 2 | B13: 45853 | E13: =IF(B13<>"",E12+C13-D13,"") -> 51000 | I13: 2
A14: =IF(B14<>"",ROW()-11,"") -> 3 | B14: 45854 | E14: =IF(B14<>"",E13+C14-D14,"") -> 51000 | I14: 3
A15: =IF(B15<>"",ROW()-11,"") -> 4 | B15: 45855 | E15: =IF(B15<>"",E14+C15-D15,"") -> 51000 | I15: 4
A16: =IF(B16<>"",ROW()-11,"") -> 5 | B16: 45856 | E16: =IF(B16<>"",E15+C16-D16,"") -> 51000 | I16: 5
A17: =IF(B17<>"",ROW()-11,"") -> 6 | B17: 45857 | E17: =IF(B17<>"",E16+C17-D17,"") -> 51000 | I17: 6
A18: =IF(B18<>"",ROW()-11,"") -> 7 | B18: 45858 | E18: =IF(B18<>"",E17+C18-D18,"") -> 51000 | I18: 7
A19: =IF(B19<>"",ROW()-11,"") -> 8 | B19: 45859 | E19: =IF(B19<>"",E18+C19-D19,"") -> 51000 | I19: 8
A20: =IF(B20<>"",ROW()-11,"") -> 9 | B20: 45860 | E20: =IF(B20<>"",E19+C20-D20,"") -> 51000 | I20: 9
A21: =IF(B21<>"",ROW()-11,"") -> 10 | B21: 45861 | C21: 2000 | E21: =IF(B21<>"",E20+C21-D21,"") -> 53000 | I21: 10
A22: =IF(B22<>"",ROW()-11,"") -> 11 | B22: 45862 | C22: 2000 | E22: =IF(B22<>"",E21+C22-D22,"") -> 55000 | I22: 11
A23: =IF(B23<>"",ROW()-11,"") -> 12 | B23: 45863 | E23: =IF(B23<>"",E22+C23-D23,"") -> 55000 | I23: 12
A24: =IF(B24<>"",ROW()-11,"") -> 13 | B24: 45864 | E24: =IF(B24<>"",E23+C24-D24,"") -> 55000 | I24: 13
A25: =IF(B25<>"",ROW()-11,"") -> 14 | B25: 45865 | E25: =IF(B25<>"",E24+C25-D25,"") -> 55000 | I25: 14
A26: =IF(B26<>"",ROW()-11,"") -> 15 | B26: 45866 | C26: 5000 | E26: =IF(B26<>"",E25+C26-D26,"") -> 60000 | I26: 15
A27: =IF(B27<>"",ROW()-11,"") -> 16 | B27: 45867 | E27: =IF(B27<>"",E26+C27-D27,"") -> 60000 | I27: 16
A28: =IF(B28<>"",ROW()-11,"") -> 17 | B28: 45868 | C28: 5000 | E28: =IF(B28<>"",E27+C28-D28,"") -> 65000 | I28: 17
A29: =IF(B29<>"",ROW()-11,"") -> 18 | B29: 45869 | E29: =IF(B29<>"",E28+C29-D29,"") -> 65000 | I29: 18
A30: =IF(B30<>"",ROW()-11,"") -> 19 | B30: 45870 | E30: =IF(B30<>"",E29+C30-D30,"") -> 65000 | I30: 19
A31: =IF(B31<>"",ROW()-11,"") -> 20 | B31: 45871 | E31: =IF(B31<>"",E30+C31-D31,"") -> 65000 | I31: 20
A32: =IF(B32<>"",ROW()-11,"") -> 21 | B32: 45872 | E32: =IF(B32<>"",E31+C32-D32,"") -> 65000 | I32: 21
A33: =IF(B33<>"",ROW()-11,"") -> 22 | B33: 45873 | C33: 5000 | E33: =IF(B33<>"",E32+C33-D33,"") -> 70000 | I33: 22
A34: =IF(B34<>"",ROW()-11,"") -> 23 | B34: 45874 | E34: =IF(B34<>"",E33+C34-D34,"") -> 70000 | I34: 23
A35: =IF(B35<>"",ROW()-11,"") -> 24 | B35: 45875 | E35: =IF(B35<>"",E34+C35-D35,"") -> 70000 | I35: 24
A36: =IF(B36<>"",ROW()-11,"") -> 25 | B36: 45876 | E36: =IF(B36<>"",E35+C36-D36,"") -> 70000 | I36: 25
A37: =IF(B37<>"",ROW()-11,"") -> 26 | B37: 45877 | C37: 5000 | E37: =IF(B37<>"",E36+C37-D37,"") -> 75000 | I37: 26
A38: =IF(B38<>"",ROW()-11,"") -> 27 | B38: 45878 | E38: =IF(B38<>"",E37+C38-D38,"") -> 75000 | I38: 27
A39: =IF(B39<>"",ROW()-11,"") -> 28 | B39: 45879 | E39: =IF(B39<>"",E38+C39-D39,"") -> 75000 | I39: 28
A40: =IF(B40<>"",ROW()-11,"") -> 29 | B40: 45880 | E40: =IF(B40<>"",E39+C40-D40,"") -> 75000 | I40: 29
A41: =IF(B41<>"",ROW()-11,"") -> 30 | B41: 45881 | C41: 5000 | E41: =IF(B41<>"",E40+C41-D41,"") -> 80000 | I41: 30
A42: =IF(B42<>"",ROW()-11,"") -> 31 | B42: 45882 | E42: =IF(B42<>"",E41+C42-D42,"") -> 80000 | I42: 31
A43: =IF(B43<>"",ROW()-11,"") -> 32 | B43: 45883 | E43: =IF(B43<>"",E42+C43-D43,"") -> 80000 | I43: 32
...

Sheet 16
A1: BUKU TABUNGAN SISWA
A3: Nama | C3: =Sheet1!C24 -> MORENO RAFAEL RADITYA NANDA
A4: NIS | C4: =Sheet1!B24 -> 231001298
A5: Kelas | C5: =Sheet1!C4 -> XII - OTKP 1
A6: Jumlah Setoran | C6: =SUM(C12:C376) -> 305000
A7: Jumlah Penarikan | C7: =SUM(D12:D376) -> 0
A8: Saldo Tabungan | C8: =SUM(C6-C7) -> 305000
A11: NO | B11: TANGGAL | C11: SETORAN | D11: PENARIKAN | E11: SALDO
A12: =IF(B12<>"",ROW()-11,"") -> 1 | B12: 45852 | C12: 125000 | E12: =IF(B12<>"",C12-D12,"") -> 125000 | I12: 1
A13: =IF(B13<>"",ROW()-11,"") -> 2 | B13: 45853 | E13: =IF(B13<>"",E12+C13-D13,"") -> 125000 | I13: 2
A14: =IF(B14<>"",ROW()-11,"") -> 3 | B14: 45854 | E14: =IF(B14<>"",E13+C14-D14,"") -> 125000 | I14: 3
A15: =IF(B15<>"",ROW()-11,"") -> 4 | B15: 45855 | E15: =IF(B15<>"",E14+C15-D15,"") -> 125000 | I15: 4
A16: =IF(B16<>"",ROW()-11,"") -> 5 | B16: 45856 | E16: =IF(B16<>"",E15+C16-D16,"") -> 125000 | I16: 5
A17: =IF(B17<>"",ROW()-11,"") -> 6 | B17: 45857 | E17: =IF(B17<>"",E16+C17-D17,"") -> 125000 | I17: 6
A18: =IF(B18<>"",ROW()-11,"") -> 7 | B18: 45858 | E18: =IF(B18<>"",E17+C18-D18,"") -> 125000 | I18: 7
A19: =IF(B19<>"",ROW()-11,"") -> 8 | B19: 45859 | E19: =IF(B19<>"",E18+C19-D19,"") -> 125000 | I19: 8
A20: =IF(B20<>"",ROW()-11,"") -> 9 | B20: 45860 | C20: 5000 | E20: =IF(B20<>"",E19+C20-D20,"") -> 130000 | I20: 9
A21: =IF(B21<>"",ROW()-11,"") -> 10 | B21: 45861 | C21: 5000 | E21: =IF(B21<>"",E20+C21-D21,"") -> 135000 | I21: 10
A22: =IF(B22<>"",ROW()-11,"") -> 11 | B22: 45862 | E22: =IF(B22<>"",E21+C22-D22,"") -> 135000 | I22: 11
A23: =IF(B23<>"",ROW()-11,"") -> 12 | B23: 45863 | E23: =IF(B23<>"",E22+C23-D23,"") -> 135000 | I23: 12
A24: =IF(B24<>"",ROW()-11,"") -> 13 | B24: 45864 | E24: =IF(B24<>"",E23+C24-D24,"") -> 135000 | I24: 13
A25: =IF(B25<>"",ROW()-11,"") -> 14 | B25: 45865 | E25: =IF(B25<>"",E24+C25-D25,"") -> 135000 | I25: 14
A26: =IF(B26<>"",ROW()-11,"") -> 15 | B26: 45866 | C26: 5000 | E26: =IF(B26<>"",E25+C26-D26,"") -> 140000 | I26: 15
A27: =IF(B27<>"",ROW()-11,"") -> 16 | B27: 45867 | E27: =IF(B27<>"",E26+C27-D27,"") -> 140000 | I27: 16
A28: =IF(B28<>"",ROW()-11,"") -> 17 | B28: 45868 | C28: 5000 | E28: =IF(B28<>"",E27+C28-D28,"") -> 145000 | I28: 17
A29: =IF(B29<>"",ROW()-11,"") -> 18 | B29: 45869 | C29: 5000 | E29: =IF(B29<>"",E28+C29-D29,"") -> 150000 | I29: 18
A30: =IF(B30<>"",ROW()-11,"") -> 19 | B30: 45870 | C30: 5000 | E30: =IF(B30<>"",E29+C30-D30,"") -> 155000 | I30: 19
A31: =IF(B31<>"",ROW()-11,"") -> 20 | B31: 45871 | E31: =IF(B31<>"",E30+C31-D31,"") -> 155000 | I31: 20
A32: =IF(B32<>"",ROW()-11,"") -> 21 | B32: 45872 | E32: =IF(B32<>"",E31+C32-D32,"") -> 155000 | I32: 21
A33: =IF(B33<>"",ROW()-11,"") -> 22 | B33: 45873 | C33: 5000 | E33: =IF(B33<>"",E32+C33-D33,"") -> 160000 | I33: 22
A34: =IF(B34<>"",ROW()-11,"") -> 23 | B34: 45874 | E34: =IF(B34<>"",E33+C34-D34,"") -> 160000 | I34: 23
A35: =IF(B35<>"",ROW()-11,"") -> 24 | B35: 45875 | C35: 5000 | E35: =IF(B35<>"",E34+C35-D35,"") -> 165000 | I35: 24
A36: =IF(B36<>"",ROW()-11,"") -> 25 | B36: 45876 | C36: 5000 | E36: =IF(B36<>"",E35+C36-D36,"") -> 170000 | I36: 25
A37: =IF(B37<>"",ROW()-11,"") -> 26 | B37: 45877 | E37: =IF(B37<>"",E36+C37-D37,"") -> 170000 | I37: 26
A38: =IF(B38<>"",ROW()-11,"") -> 27 | B38: 45878 | E38: =IF(B38<>"",E37+C38-D38,"") -> 170000 | I38: 27
